<?xml version="1.0" ?>
<robot name="queen">
	<origin xyz="0.000000e+00 0.000000e+00 2.500000e-01" rpy="0.000000e+00 -0.000000e+00 0.000000e+00"/>
	<joint name="component_F_ActiveHinge__joint" type="revolute">
		<origin xyz="1.734723e-18 7.800000e-02 -1.859624e-18" rpy="1.570796e+00 5.551115e-17 1.570796e+00"/>
		<parent link="Core"/>
		<child link="F_Leg"/>
		<axis xyz="0.000000e+00 1.000000e+00 0.000000e+00"/>
		<use_parent_model_frame>0</use_parent_model_frame>
		<limit lower="-1.5707963267948966" upper="1.5707963267948966" effort="0.9212" velocity="5.235988"/>
	</joint>
	<joint name="component_L_ActiveHinge__joint" type="revolute">
		<origin xyz="-7.800000e-02 0.000000e+00 0.000000e+00" rpy="1.570796e+00 -0.000000e+00 3.141593e+00"/>
		<parent link="Core"/>
		<child link="L_Leg"/>
		<axis xyz="0.000000e+00 1.000000e+00 0.000000e+00"/>
		<use_parent_model_frame>0</use_parent_model_frame>
		<limit lower="-1.5707963267948966" upper="1.5707963267948966" effort="0.9212" velocity="5.235988"/>
	</joint>
	<joint name="component_LF_ActiveHinge__joint" type="revolute">
		<origin xyz="7.280000e-02 0.000000e+00 0.000000e+00" rpy="0.000000e+00 -0.000000e+00 0.000000e+00"/>
		<parent link="L_Leg"/>
		<child link="LF_Leg"/>
		<axis xyz="0.000000e+00 1.000000e+00 0.000000e+00"/>
		<use_parent_model_frame>0</use_parent_model_frame>
		<limit lower="-1.5707963267948966" upper="1.5707963267948966" effort="0.9212" velocity="5.235988"/>
	</joint>
	<joint name="component_LFF_ActiveHinge__joint" type="revolute">
		<origin xyz="7.280000e-02 0.000000e+00 0.000000e+00" rpy="-1.570796e+00 0.000000e+00 0.000000e+00"/>
		<parent link="LF_Leg"/>
		<child link="LFF_Leg"/>
		<axis xyz="0.000000e+00 1.000000e+00 0.000000e+00"/>
		<use_parent_model_frame>0</use_parent_model_frame>
		<limit lower="-1.5707963267948966" upper="1.5707963267948966" effort="0.9212" velocity="5.235988"/>
	</joint>
	<joint name="component_LFFFRFR_ActiveHinge__joint" type="revolute">
		<origin xyz="5.800000e-03 -1.257725e-01 0.000000e+00" rpy="0.000000e+00 -0.000000e+00 3.141593e+00"/>
		<parent link="LFF_Leg"/>
		<child link="LFFFRFR_Leg"/>
		<axis xyz="0.000000e+00 1.000000e+00 0.000000e+00"/>
		<use_parent_model_frame>0</use_parent_model_frame>
		<limit lower="-1.5707963267948966" upper="1.5707963267948966" effort="0.9212" velocity="5.235988"/>
	</joint>
	<joint name="component_LFFFRFL_ActiveHinge__joint" type="revolute">
		<origin xyz="1.356863e-01 -1.257725e-01 0.000000e+00" rpy="0.000000e+00 -0.000000e+00 0.000000e+00"/>
		<parent link="LFF_Leg"/>
		<child link="LFFFRFL_Leg"/>
		<axis xyz="0.000000e+00 1.000000e+00 0.000000e+00"/>
		<use_parent_model_frame>0</use_parent_model_frame>
		<limit lower="-1.5707963267948966" upper="1.5707963267948966" effort="0.9212" velocity="5.235988"/>
	</joint>
	<joint name="component_LFFFRRF_ActiveHinge__joint" type="revolute">
		<origin xyz="-5.708625e-02 -6.288625e-02 0.000000e+00" rpy="1.570796e+00 -0.000000e+00 3.141593e+00"/>
		<parent link="LFF_Leg"/>
		<child link="LFFFRRF_Leg"/>
		<axis xyz="0.000000e+00 1.000000e+00 0.000000e+00"/>
		<use_parent_model_frame>0</use_parent_model_frame>
		<limit lower="-1.5707963267948966" upper="1.5707963267948966" effort="0.9212" velocity="5.235988"/>
	</joint>
	<joint name="component_LFFFRRFF_ActiveHinge__joint" type="revolute">
		<origin xyz="7.280000e-02 0.000000e+00 0.000000e+00" rpy="0.000000e+00 -0.000000e+00 0.000000e+00"/>
		<parent link="LFFFRRF_Leg"/>
		<child link="LFFFRRFF_Leg"/>
		<axis xyz="0.000000e+00 1.000000e+00 0.000000e+00"/>
		<use_parent_model_frame>0</use_parent_model_frame>
		<limit lower="-1.5707963267948966" upper="1.5707963267948966" effort="0.9212" velocity="5.235988"/>
	</joint>
	<joint name="component_LFFFL_ActiveHinge__joint" type="revolute">
		<origin xyz="7.074313e-02 6.494313e-02 0.000000e+00" rpy="0.000000e+00 -0.000000e+00 1.570796e+00"/>
		<parent link="LFF_Leg"/>
		<child link="LFFFL_Leg"/>
		<axis xyz="0.000000e+00 1.000000e+00 0.000000e+00"/>
		<use_parent_model_frame>0</use_parent_model_frame>
		<limit lower="-1.5707963267948966" upper="1.5707963267948966" effort="0.9212" velocity="5.235988"/>
	</joint>
	<link name="Core">
		<origin xyz="-2.714614e-03 2.714614e-03 -5.079168e-20" rpy="0.000000e+00 -0.000000e+00 0.000000e+00"/>
		<sensor name="core-imu_sensor" type="imu">
			<origin xyz="0.000000e+00 0.000000e+00 0.000000e+00" rpy="0.000000e+00 -0.000000e+00 0.000000e+00"/>
			<always_on>True</always_on>
		</sensor>
		<visual name="component__CoreComponent__box_visual">
			<origin xyz="0.000000e+00 0.000000e+00 0.000000e+00" rpy="0.000000e+00 -0.000000e+00 0.000000e+00"/>
			<material name="no_texture">
				<color rgba="1 1 0 1.0"/>
			</material>
			<geometry>
				<mesh filename="package://models/rg_robot/meshes/CoreComponent.dae"/>
			</geometry>
		</visual>
		<collision name="component__CoreComponent__box_collision">
			<origin xyz="0.000000e+00 0.000000e+00 0.000000e+00" rpy="0.000000e+00 -0.000000e+00 0.000000e+00"/>
			<contact>
				<lateral_friction value="0.8"/>
				<rolling_friction value="0"/>
				<spinning_friction value="1"/>
				<stiffness value="90000"/>
				<damping value="3333333.3333333335"/>
			</contact>
			<gazebo name="component__CoreComponent__box">
				<mu1 value="1.0"/>
				<mu2 value="1.0"/>
				<slip1 value="0.01"/>
				<slip2 value="0.01"/>
			</gazebo>
			<geometry>
				<box size="8.900000e-02 8.900000e-02 6.030000e-02"/>
			</geometry>
		</collision>
		<visual name="component_F_ActiveHinge__frame_visual">
			<origin xyz="5.204170e-18 6.712500e-02 -1.255940e-18" rpy="1.570796e+00 5.551115e-17 1.570796e+00"/>
			<material name="no_texture">
				<color rgba="0.7 0 0 1.0"/>
			</material>
			<geometry>
				<mesh filename="package://models/rg_robot/meshes/ActiveHinge_Frame.dae"/>
			</geometry>
		</visual>
		<collision name="component_F_ActiveHinge__frame_collision">
			<origin xyz="5.204170e-18 6.712500e-02 -1.255940e-18" rpy="1.570796e+00 5.551115e-17 1.570796e+00"/>
			<contact>
				<lateral_friction value="0.8"/>
				<rolling_friction value="0"/>
				<spinning_friction value="1"/>
				<stiffness value="90000"/>
				<damping value="3333333.3333333335"/>
			</contact>
			<gazebo name="component_F_ActiveHinge__frame">
				<mu1 value="1.0"/>
				<mu2 value="1.0"/>
				<slip1 value="0.01"/>
				<slip2 value="0.01"/>
			</gazebo>
			<geometry>
				<box size="4.525000e-02 5.300000e-02 1.658910e-02"/>
			</geometry>
		</collision>
		<visual name="component_L_ActiveHinge__frame_visual">
			<origin xyz="-6.712500e-02 0.000000e+00 0.000000e+00" rpy="1.570796e+00 -0.000000e+00 3.141593e+00"/>
			<material name="no_texture">
				<color rgba="0.7 0 0 1.0"/>
			</material>
			<geometry>
				<mesh filename="package://models/rg_robot/meshes/ActiveHinge_Frame.dae"/>
			</geometry>
		</visual>
		<collision name="component_L_ActiveHinge__frame_collision">
			<origin xyz="-6.712500e-02 0.000000e+00 0.000000e+00" rpy="1.570796e+00 -0.000000e+00 3.141593e+00"/>
			<contact>
				<lateral_friction value="0.8"/>
				<rolling_friction value="0"/>
				<spinning_friction value="1"/>
				<stiffness value="90000"/>
				<damping value="3333333.3333333335"/>
			</contact>
			<gazebo name="component_L_ActiveHinge__frame">
				<mu1 value="1.0"/>
				<mu2 value="1.0"/>
				<slip1 value="0.01"/>
				<slip2 value="0.01"/>
			</gazebo>
			<geometry>
				<box size="4.525000e-02 5.300000e-02 1.658910e-02"/>
			</geometry>
		</collision>
		<inertial>
			<origin xyz="-2.714614e-03 2.714614e-03 -5.079168e-20" rpy="0.000000e+00 -0.000000e+00 0.000000e+00"/>
			<mass value="0.272"/>
			<inertia ixx="0.00029561075779504267" ixy="-2.00440309053309e-06" ixz="1.4020726778485858e-21" iyy="0.00029561075779504267" iyz="1.4420763010178737e-21" izz="0.00042941809892341876"/>
		</inertial>
	</link>
	<link name="F_Leg">
		<origin xyz="1.015000e-02 0.000000e+00 0.000000e+00" rpy="0.000000e+00 -0.000000e+00 0.000000e+00"/>
		<visual name="component_F_ActiveHinge__servo_visual">
			<origin xyz="2.990000e-02 0.000000e+00 0.000000e+00" rpy="0.000000e+00 -0.000000e+00 0.000000e+00"/>
			<material name="no_texture">
				<color rgba="0.7 0 0 1.0"/>
			</material>
			<geometry>
				<mesh filename="package://models/rg_robot/meshes/ActiveCardanHinge_Servo_Holder.dae"/>
			</geometry>
		</visual>
		<collision name="component_F_ActiveHinge__servo_collision">
			<origin xyz="1.015000e-02 0.000000e+00 0.000000e+00" rpy="0.000000e+00 -0.000000e+00 0.000000e+00"/>
			<contact>
				<lateral_friction value="0.8"/>
				<rolling_friction value="0"/>
				<spinning_friction value="1"/>
				<stiffness value="90000"/>
				<damping value="3333333.3333333335"/>
			</contact>
			<gazebo name="component_F_ActiveHinge__servo">
				<mu1 value="1.0"/>
				<mu2 value="1.0"/>
				<slip1 value="0.01"/>
				<slip2 value="0.01"/>
			</gazebo>
			<geometry>
				<box size="5.830000e-02 5.120000e-02 2.000000e-02"/>
			</geometry>
		</collision>
		<collision name="component_F_ActiveHinge__servo2_collision">
			<origin xyz="3.830000e-02 0.000000e+00 0.000000e+00" rpy="0.000000e+00 -0.000000e+00 0.000000e+00"/>
			<contact>
				<lateral_friction value="0.8"/>
				<rolling_friction value="0"/>
				<spinning_friction value="1"/>
				<stiffness value="90000"/>
				<damping value="3333333.3333333335"/>
			</contact>
			<gazebo name="component_F_ActiveHinge__servo2">
				<mu1 value="1.0"/>
				<mu2 value="1.0"/>
				<slip1 value="0.01"/>
				<slip2 value="0.01"/>
			</gazebo>
			<geometry>
				<box size="2.000000e-03 5.300000e-02 5.300000e-02"/>
			</geometry>
		</collision>
		<inertial>
			<origin xyz="1.015000e-02 0.000000e+00 0.000000e+00" rpy="0.000000e+00 -0.000000e+00 0.000000e+00"/>
			<mass value="0.058"/>
			<inertia ixx="1.460362666666667e-05" ixy="0.0" ixz="0.0" iyy="1.836130166666667e-05" iyz="0.0" izz="2.909826166666667e-05"/>
		</inertial>
	</link>
	<link name="L_Leg">
		<origin xyz="1.840399e-02 0.000000e+00 0.000000e+00" rpy="0.000000e+00 -0.000000e+00 0.000000e+00"/>
		<visual name="component_L_ActiveHinge__servo_visual">
			<origin xyz="2.990000e-02 0.000000e+00 0.000000e+00" rpy="0.000000e+00 -0.000000e+00 0.000000e+00"/>
			<material name="no_texture">
				<color rgba="0.7 0 0 1.0"/>
			</material>
			<geometry>
				<mesh filename="package://models/rg_robot/meshes/ActiveCardanHinge_Servo_Holder.dae"/>
			</geometry>
		</visual>
		<collision name="component_L_ActiveHinge__servo_collision">
			<origin xyz="1.015000e-02 0.000000e+00 0.000000e+00" rpy="0.000000e+00 -0.000000e+00 0.000000e+00"/>
			<contact>
				<lateral_friction value="0.8"/>
				<rolling_friction value="0"/>
				<spinning_friction value="1"/>
				<stiffness value="90000"/>
				<damping value="3333333.3333333335"/>
			</contact>
			<gazebo name="component_L_ActiveHinge__servo">
				<mu1 value="1.0"/>
				<mu2 value="1.0"/>
				<slip1 value="0.01"/>
				<slip2 value="0.01"/>
			</gazebo>
			<geometry>
				<box size="5.830000e-02 5.120000e-02 2.000000e-02"/>
			</geometry>
		</collision>
		<collision name="component_L_ActiveHinge__servo2_collision">
			<origin xyz="3.830000e-02 0.000000e+00 0.000000e+00" rpy="0.000000e+00 -0.000000e+00 0.000000e+00"/>
			<contact>
				<lateral_friction value="0.8"/>
				<rolling_friction value="0"/>
				<spinning_friction value="1"/>
				<stiffness value="90000"/>
				<damping value="3333333.3333333335"/>
			</contact>
			<gazebo name="component_L_ActiveHinge__servo2">
				<mu1 value="1.0"/>
				<mu2 value="1.0"/>
				<slip1 value="0.01"/>
				<slip2 value="0.01"/>
			</gazebo>
			<geometry>
				<box size="2.000000e-03 5.300000e-02 5.300000e-02"/>
			</geometry>
		</collision>
		<visual name="component_LF_ActiveHinge__frame_visual">
			<origin xyz="6.192500e-02 0.000000e+00 0.000000e+00" rpy="0.000000e+00 -0.000000e+00 0.000000e+00"/>
			<material name="no_texture">
				<color rgba="0.7 0 0 1.0"/>
			</material>
			<geometry>
				<mesh filename="package://models/rg_robot/meshes/ActiveHinge_Frame.dae"/>
			</geometry>
		</visual>
		<collision name="component_LF_ActiveHinge__frame_collision">
			<origin xyz="6.192500e-02 0.000000e+00 0.000000e+00" rpy="0.000000e+00 -0.000000e+00 0.000000e+00"/>
			<contact>
				<lateral_friction value="0.8"/>
				<rolling_friction value="0"/>
				<spinning_friction value="1"/>
				<stiffness value="90000"/>
				<damping value="3333333.3333333335"/>
			</contact>
			<gazebo name="component_LF_ActiveHinge__frame">
				<mu1 value="1.0"/>
				<mu2 value="1.0"/>
				<slip1 value="0.01"/>
				<slip2 value="0.01"/>
			</gazebo>
			<geometry>
				<box size="4.525000e-02 5.300000e-02 1.658910e-02"/>
			</geometry>
		</collision>
		<inertial>
			<origin xyz="1.840399e-02 0.000000e+00 0.000000e+00" rpy="0.000000e+00 -0.000000e+00 0.000000e+00"/>
			<mass value="0.069"/>
			<inertia ixx="1.7430808385575836e-05" ixy="0.0" ixz="0.0" iyy="4.5276804789561346e-05" iyz="0.0" izz="5.83364164039855e-05"/>
		</inertial>
	</link>
	<link name="LF_Leg">
		<origin xyz="1.840399e-02 0.000000e+00 0.000000e+00" rpy="0.000000e+00 -0.000000e+00 0.000000e+00"/>
		<visual name="component_LF_ActiveHinge__servo_visual">
			<origin xyz="2.990000e-02 0.000000e+00 0.000000e+00" rpy="0.000000e+00 -0.000000e+00 0.000000e+00"/>
			<material name="no_texture">
				<color rgba="0.7 0 0 1.0"/>
			</material>
			<geometry>
				<mesh filename="package://models/rg_robot/meshes/ActiveCardanHinge_Servo_Holder.dae"/>
			</geometry>
		</visual>
		<collision name="component_LF_ActiveHinge__servo_collision">
			<origin xyz="1.015000e-02 0.000000e+00 0.000000e+00" rpy="0.000000e+00 -0.000000e+00 0.000000e+00"/>
			<contact>
				<lateral_friction value="0.8"/>
				<rolling_friction value="0"/>
				<spinning_friction value="1"/>
				<stiffness value="90000"/>
				<damping value="3333333.3333333335"/>
			</contact>
			<gazebo name="component_LF_ActiveHinge__servo">
				<mu1 value="1.0"/>
				<mu2 value="1.0"/>
				<slip1 value="0.01"/>
				<slip2 value="0.01"/>
			</gazebo>
			<geometry>
				<box size="5.830000e-02 5.120000e-02 2.000000e-02"/>
			</geometry>
		</collision>
		<collision name="component_LF_ActiveHinge__servo2_collision">
			<origin xyz="3.830000e-02 0.000000e+00 0.000000e+00" rpy="0.000000e+00 -0.000000e+00 0.000000e+00"/>
			<contact>
				<lateral_friction value="0.8"/>
				<rolling_friction value="0"/>
				<spinning_friction value="1"/>
				<stiffness value="90000"/>
				<damping value="3333333.3333333335"/>
			</contact>
			<gazebo name="component_LF_ActiveHinge__servo2">
				<mu1 value="1.0"/>
				<mu2 value="1.0"/>
				<slip1 value="0.01"/>
				<slip2 value="0.01"/>
			</gazebo>
			<geometry>
				<box size="2.000000e-03 5.300000e-02 5.300000e-02"/>
			</geometry>
		</collision>
		<visual name="component_LFF_ActiveHinge__frame_visual">
			<origin xyz="6.192500e-02 0.000000e+00 0.000000e+00" rpy="-1.570796e+00 0.000000e+00 0.000000e+00"/>
			<material name="no_texture">
				<color rgba="1 0.08 0.58 1.0"/>
			</material>
			<geometry>
				<mesh filename="package://models/rg_robot/meshes/ActiveHinge_Frame.dae"/>
			</geometry>
		</visual>
		<collision name="component_LFF_ActiveHinge__frame_collision">
			<origin xyz="6.192500e-02 0.000000e+00 0.000000e+00" rpy="-1.570796e+00 0.000000e+00 0.000000e+00"/>
			<contact>
				<lateral_friction value="0.8"/>
				<rolling_friction value="0"/>
				<spinning_friction value="1"/>
				<stiffness value="90000"/>
				<damping value="3333333.3333333335"/>
			</contact>
			<gazebo name="component_LFF_ActiveHinge__frame">
				<mu1 value="1.0"/>
				<mu2 value="1.0"/>
				<slip1 value="0.01"/>
				<slip2 value="0.01"/>
			</gazebo>
			<geometry>
				<box size="4.525000e-02 5.300000e-02 1.658910e-02"/>
			</geometry>
		</collision>
		<inertial>
			<origin xyz="1.840399e-02 0.000000e+00 0.000000e+00" rpy="0.000000e+00 -0.000000e+00 0.000000e+00"/>
			<mass value="0.069"/>
			<inertia ixx="1.7430808385575836e-05" ixy="0.0" ixz="0.0" iyy="4.759945640398551e-05" iyz="-1.0314645202066005e-21" izz="5.601376478956134e-05"/>
		</inertial>
	</link>
	<link name="LFF_Leg">
		<origin xyz="4.061931e-02 -4.689344e-02 0.000000e+00" rpy="0.000000e+00 -0.000000e+00 0.000000e+00"/>
		<visual name="component_LFF_ActiveHinge__servo_visual">
			<origin xyz="2.990000e-02 0.000000e+00 0.000000e+00" rpy="0.000000e+00 -0.000000e+00 0.000000e+00"/>
			<material name="no_texture">
				<color rgba="1 0.08 0.58 1.0"/>
			</material>
			<geometry>
				<mesh filename="package://models/rg_robot/meshes/ActiveCardanHinge_Servo_Holder.dae"/>
			</geometry>
		</visual>
		<collision name="component_LFF_ActiveHinge__servo_collision">
			<origin xyz="1.015000e-02 0.000000e+00 0.000000e+00" rpy="0.000000e+00 -0.000000e+00 0.000000e+00"/>
			<contact>
				<lateral_friction value="0.8"/>
				<rolling_friction value="0"/>
				<spinning_friction value="1"/>
				<stiffness value="90000"/>
				<damping value="3333333.3333333335"/>
			</contact>
			<gazebo name="component_LFF_ActiveHinge__servo">
				<mu1 value="1.0"/>
				<mu2 value="1.0"/>
				<slip1 value="0.01"/>
				<slip2 value="0.01"/>
			</gazebo>
			<geometry>
				<box size="5.830000e-02 5.120000e-02 2.000000e-02"/>
			</geometry>
		</collision>
		<collision name="component_LFF_ActiveHinge__servo2_collision">
			<origin xyz="3.830000e-02 0.000000e+00 0.000000e+00" rpy="0.000000e+00 -0.000000e+00 0.000000e+00"/>
			<contact>
				<lateral_friction value="0.8"/>
				<rolling_friction value="0"/>
				<spinning_friction value="1"/>
				<stiffness value="90000"/>
				<damping value="3333333.3333333335"/>
			</contact>
			<gazebo name="component_LFF_ActiveHinge__servo2">
				<mu1 value="1.0"/>
				<mu2 value="1.0"/>
				<slip1 value="0.01"/>
				<slip2 value="0.01"/>
			</gazebo>
			<geometry>
				<box size="2.000000e-03 5.300000e-02 5.300000e-02"/>
			</geometry>
		</collision>
		<visual name="component_LFFF_FixedBrick__box_visual">
			<origin xyz="7.074313e-02 0.000000e+00 0.000000e+00" rpy="0.000000e+00 0.000000e+00 -1.570796e+00"/>
			<material name="no_texture">
				<color rgba="0 0 1 1.0"/>
			</material>
			<geometry>
				<mesh filename="package://models/rg_robot/meshes/FixedBrick.dae"/>
			</geometry>
		</visual>
		<collision name="component_LFFF_FixedBrick__box_collision">
			<origin xyz="7.074313e-02 0.000000e+00 0.000000e+00" rpy="0.000000e+00 0.000000e+00 -1.570796e+00"/>
			<contact>
				<lateral_friction value="0.8"/>
				<rolling_friction value="0"/>
				<spinning_friction value="1"/>
				<stiffness value="90000"/>
				<damping value="3333333.3333333335"/>
			</contact>
			<gazebo name="component_LFFF_FixedBrick__box">
				<mu1 value="1.0"/>
				<mu2 value="1.0"/>
				<slip1 value="0.01"/>
				<slip2 value="0.01"/>
			</gazebo>
			<geometry>
				<box size="6.288625e-02 6.288625e-02 6.030000e-02"/>
			</geometry>
		</collision>
		<visual name="component_LFFFR_FixedBrick__box_visual">
			<origin xyz="7.074313e-02 -6.288625e-02 0.000000e+00" rpy="0.000000e+00 -0.000000e+00 3.141593e+00"/>
			<material name="no_texture">
				<color rgba="0 0 1 1.0"/>
			</material>
			<geometry>
				<mesh filename="package://models/rg_robot/meshes/FixedBrick.dae"/>
			</geometry>
		</visual>
		<collision name="component_LFFFR_FixedBrick__box_collision">
			<origin xyz="7.074313e-02 -6.288625e-02 0.000000e+00" rpy="0.000000e+00 -0.000000e+00 3.141593e+00"/>
			<contact>
				<lateral_friction value="0.8"/>
				<rolling_friction value="0"/>
				<spinning_friction value="1"/>
				<stiffness value="90000"/>
				<damping value="3333333.3333333335"/>
			</contact>
			<gazebo name="component_LFFFR_FixedBrick__box">
				<mu1 value="1.0"/>
				<mu2 value="1.0"/>
				<slip1 value="0.01"/>
				<slip2 value="0.01"/>
			</gazebo>
			<geometry>
				<box size="6.288625e-02 6.288625e-02 6.030000e-02"/>
			</geometry>
		</collision>
		<visual name="component_LFFFRF_FixedBrick__box_visual">
			<origin xyz="7.074313e-02 -1.257725e-01 0.000000e+00" rpy="0.000000e+00 -0.000000e+00 3.141593e+00"/>
			<material name="no_texture">
				<color rgba="0 0 1 1.0"/>
			</material>
			<geometry>
				<mesh filename="package://models/rg_robot/meshes/FixedBrick.dae"/>
			</geometry>
		</visual>
		<collision name="component_LFFFRF_FixedBrick__box_collision">
			<origin xyz="7.074313e-02 -1.257725e-01 0.000000e+00" rpy="0.000000e+00 -0.000000e+00 3.141593e+00"/>
			<contact>
				<lateral_friction value="0.8"/>
				<rolling_friction value="0"/>
				<spinning_friction value="1"/>
				<stiffness value="90000"/>
				<damping value="3333333.3333333335"/>
			</contact>
			<gazebo name="component_LFFFRF_FixedBrick__box">
				<mu1 value="1.0"/>
				<mu2 value="1.0"/>
				<slip1 value="0.01"/>
				<slip2 value="0.01"/>
			</gazebo>
			<geometry>
				<box size="6.288625e-02 6.288625e-02 6.030000e-02"/>
			</geometry>
		</collision>
		<visual name="component_LFFFRFR_ActiveHinge__frame_visual">
			<origin xyz="1.667500e-02 -1.257725e-01 0.000000e+00" rpy="0.000000e+00 -0.000000e+00 3.141593e+00"/>
			<material name="no_texture">
				<color rgba="1 0.08 0.58 1.0"/>
			</material>
			<geometry>
				<mesh filename="package://models/rg_robot/meshes/ActiveHinge_Frame.dae"/>
			</geometry>
		</visual>
		<collision name="component_LFFFRFR_ActiveHinge__frame_collision">
			<origin xyz="1.667500e-02 -1.257725e-01 0.000000e+00" rpy="0.000000e+00 -0.000000e+00 3.141593e+00"/>
			<contact>
				<lateral_friction value="0.8"/>
				<rolling_friction value="0"/>
				<spinning_friction value="1"/>
				<stiffness value="90000"/>
				<damping value="3333333.3333333335"/>
			</contact>
			<gazebo name="component_LFFFRFR_ActiveHinge__frame">
				<mu1 value="1.0"/>
				<mu2 value="1.0"/>
				<slip1 value="0.01"/>
				<slip2 value="0.01"/>
			</gazebo>
			<geometry>
				<box size="4.525000e-02 5.300000e-02 1.658910e-02"/>
			</geometry>
		</collision>
		<visual name="component_LFFFRFL_ActiveHinge__frame_visual">
			<origin xyz="1.248113e-01 -1.257725e-01 0.000000e+00" rpy="0.000000e+00 -0.000000e+00 0.000000e+00"/>
			<material name="no_texture">
				<color rgba="1 0.08 0.58 1.0"/>
			</material>
			<geometry>
				<mesh filename="package://models/rg_robot/meshes/ActiveHinge_Frame.dae"/>
			</geometry>
		</visual>
		<collision name="component_LFFFRFL_ActiveHinge__frame_collision">
			<origin xyz="1.248113e-01 -1.257725e-01 0.000000e+00" rpy="0.000000e+00 -0.000000e+00 0.000000e+00"/>
			<contact>
				<lateral_friction value="0.8"/>
				<rolling_friction value="0"/>
				<spinning_friction value="1"/>
				<stiffness value="90000"/>
				<damping value="3333333.3333333335"/>
			</contact>
			<gazebo name="component_LFFFRFL_ActiveHinge__frame">
				<mu1 value="1.0"/>
				<mu2 value="1.0"/>
				<slip1 value="0.01"/>
				<slip2 value="0.01"/>
			</gazebo>
			<geometry>
				<box size="4.525000e-02 5.300000e-02 1.658910e-02"/>
			</geometry>
		</collision>
		<visual name="component_LFFFRR_FixedBrick__box_visual">
			<origin xyz="7.856875e-03 -6.288625e-02 0.000000e+00" rpy="0.000000e+00 -0.000000e+00 1.570796e+00"/>
			<material name="no_texture">
				<color rgba="0 0 1 1.0"/>
			</material>
			<geometry>
				<mesh filename="package://models/rg_robot/meshes/FixedBrick.dae"/>
			</geometry>
		</visual>
		<collision name="component_LFFFRR_FixedBrick__box_collision">
			<origin xyz="7.856875e-03 -6.288625e-02 0.000000e+00" rpy="0.000000e+00 -0.000000e+00 1.570796e+00"/>
			<contact>
				<lateral_friction value="0.8"/>
				<rolling_friction value="0"/>
				<spinning_friction value="1"/>
				<stiffness value="90000"/>
				<damping value="3333333.3333333335"/>
			</contact>
			<gazebo name="component_LFFFRR_FixedBrick__box">
				<mu1 value="1.0"/>
				<mu2 value="1.0"/>
				<slip1 value="0.01"/>
				<slip2 value="0.01"/>
			</gazebo>
			<geometry>
				<box size="6.288625e-02 6.288625e-02 6.030000e-02"/>
			</geometry>
		</collision>
		<visual name="component_LFFFRRF_ActiveHinge__frame_visual">
			<origin xyz="-4.621125e-02 -6.288625e-02 0.000000e+00" rpy="1.570796e+00 -0.000000e+00 3.141593e+00"/>
			<material name="no_texture">
				<color rgba="0.7 0 0 1.0"/>
			</material>
			<geometry>
				<mesh filename="package://models/rg_robot/meshes/ActiveHinge_Frame.dae"/>
			</geometry>
		</visual>
		<collision name="component_LFFFRRF_ActiveHinge__frame_collision">
			<origin xyz="-4.621125e-02 -6.288625e-02 0.000000e+00" rpy="1.570796e+00 -0.000000e+00 3.141593e+00"/>
			<contact>
				<lateral_friction value="0.8"/>
				<rolling_friction value="0"/>
				<spinning_friction value="1"/>
				<stiffness value="90000"/>
				<damping value="3333333.3333333335"/>
			</contact>
			<gazebo name="component_LFFFRRF_ActiveHinge__frame">
				<mu1 value="1.0"/>
				<mu2 value="1.0"/>
				<slip1 value="0.01"/>
				<slip2 value="0.01"/>
			</gazebo>
			<geometry>
				<box size="4.525000e-02 5.300000e-02 1.658910e-02"/>
			</geometry>
		</collision>
		<visual name="component_LFFFL_ActiveHinge__frame_visual">
			<origin xyz="7.074313e-02 5.406813e-02 0.000000e+00" rpy="0.000000e+00 -0.000000e+00 1.570796e+00"/>
			<material name="no_texture">
				<color rgba="1 0.08 0.58 1.0"/>
			</material>
			<geometry>
				<mesh filename="package://models/rg_robot/meshes/ActiveHinge_Frame.dae"/>
			</geometry>
		</visual>
		<collision name="component_LFFFL_ActiveHinge__frame_collision">
			<origin xyz="7.074313e-02 5.406813e-02 0.000000e+00" rpy="0.000000e+00 -0.000000e+00 1.570796e+00"/>
			<contact>
				<lateral_friction value="0.8"/>
				<rolling_friction value="0"/>
				<spinning_friction value="1"/>
				<stiffness value="90000"/>
				<damping value="3333333.3333333335"/>
			</contact>
			<gazebo name="component_LFFFL_ActiveHinge__frame">
				<mu1 value="1.0"/>
				<mu2 value="1.0"/>
				<slip1 value="0.01"/>
				<slip2 value="0.01"/>
			</gazebo>
			<geometry>
				<box size="4.525000e-02 5.300000e-02 1.658910e-02"/>
			</geometry>
		</collision>
		<inertial>
			<origin xyz="4.061931e-02 -4.689344e-02 0.000000e+00" rpy="0.000000e+00 -0.000000e+00 0.000000e+00"/>
			<mass value="0.22200000000000003"/>
			<inertia ixx="0.0007484580076881953" ixy="0.0001140558295744951" ixz="0.0" iyy="0.00045071833430540624" iyz="0.0" izz="0.0011159244516801463"/>
		</inertial>
	</link>
	<link name="LFFFRFR_Leg">
		<origin xyz="1.015000e-02 0.000000e+00 0.000000e+00" rpy="0.000000e+00 -0.000000e+00 0.000000e+00"/>
		<visual name="component_LFFFRFR_ActiveHinge__servo_visual">
			<origin xyz="2.990000e-02 0.000000e+00 0.000000e+00" rpy="0.000000e+00 -0.000000e+00 0.000000e+00"/>
			<material name="no_texture">
				<color rgba="1 0.08 0.58 1.0"/>
			</material>
			<geometry>
				<mesh filename="package://models/rg_robot/meshes/ActiveCardanHinge_Servo_Holder.dae"/>
			</geometry>
		</visual>
		<collision name="component_LFFFRFR_ActiveHinge__servo_collision">
			<origin xyz="1.015000e-02 0.000000e+00 0.000000e+00" rpy="0.000000e+00 -0.000000e+00 0.000000e+00"/>
			<contact>
				<lateral_friction value="0.8"/>
				<rolling_friction value="0"/>
				<spinning_friction value="1"/>
				<stiffness value="90000"/>
				<damping value="3333333.3333333335"/>
			</contact>
			<gazebo name="component_LFFFRFR_ActiveHinge__servo">
				<mu1 value="1.0"/>
				<mu2 value="1.0"/>
				<slip1 value="0.01"/>
				<slip2 value="0.01"/>
			</gazebo>
			<geometry>
				<box size="5.830000e-02 5.120000e-02 2.000000e-02"/>
			</geometry>
		</collision>
		<collision name="component_LFFFRFR_ActiveHinge__servo2_collision">
			<origin xyz="3.830000e-02 0.000000e+00 0.000000e+00" rpy="0.000000e+00 -0.000000e+00 0.000000e+00"/>
			<contact>
				<lateral_friction value="0.8"/>
				<rolling_friction value="0"/>
				<spinning_friction value="1"/>
				<stiffness value="90000"/>
				<damping value="3333333.3333333335"/>
			</contact>
			<gazebo name="component_LFFFRFR_ActiveHinge__servo2">
				<mu1 value="1.0"/>
				<mu2 value="1.0"/>
				<slip1 value="0.01"/>
				<slip2 value="0.01"/>
			</gazebo>
			<geometry>
				<box size="2.000000e-03 5.300000e-02 5.300000e-02"/>
			</geometry>
		</collision>
		<inertial>
			<origin xyz="1.015000e-02 0.000000e+00 0.000000e+00" rpy="0.000000e+00 -0.000000e+00 0.000000e+00"/>
			<mass value="0.058"/>
			<inertia ixx="1.460362666666667e-05" ixy="0.0" ixz="0.0" iyy="1.836130166666667e-05" iyz="0.0" izz="2.909826166666667e-05"/>
		</inertial>
	</link>
	<link name="LFFFRFL_Leg">
		<origin xyz="1.015000e-02 0.000000e+00 0.000000e+00" rpy="0.000000e+00 -0.000000e+00 0.000000e+00"/>
		<visual name="component_LFFFRFL_ActiveHinge__servo_visual">
			<origin xyz="2.990000e-02 0.000000e+00 0.000000e+00" rpy="0.000000e+00 -0.000000e+00 0.000000e+00"/>
			<material name="no_texture">
				<color rgba="1 0.08 0.58 1.0"/>
			</material>
			<geometry>
				<mesh filename="package://models/rg_robot/meshes/ActiveCardanHinge_Servo_Holder.dae"/>
			</geometry>
		</visual>
		<collision name="component_LFFFRFL_ActiveHinge__servo_collision">
			<origin xyz="1.015000e-02 0.000000e+00 0.000000e+00" rpy="0.000000e+00 -0.000000e+00 0.000000e+00"/>
			<contact>
				<lateral_friction value="0.8"/>
				<rolling_friction value="0"/>
				<spinning_friction value="1"/>
				<stiffness value="90000"/>
				<damping value="3333333.3333333335"/>
			</contact>
			<gazebo name="component_LFFFRFL_ActiveHinge__servo">
				<mu1 value="1.0"/>
				<mu2 value="1.0"/>
				<slip1 value="0.01"/>
				<slip2 value="0.01"/>
			</gazebo>
			<geometry>
				<box size="5.830000e-02 5.120000e-02 2.000000e-02"/>
			</geometry>
		</collision>
		<collision name="component_LFFFRFL_ActiveHinge__servo2_collision">
			<origin xyz="3.830000e-02 0.000000e+00 0.000000e+00" rpy="0.000000e+00 -0.000000e+00 0.000000e+00"/>
			<contact>
				<lateral_friction value="0.8"/>
				<rolling_friction value="0"/>
				<spinning_friction value="1"/>
				<stiffness value="90000"/>
				<damping value="3333333.3333333335"/>
			</contact>
			<gazebo name="component_LFFFRFL_ActiveHinge__servo2">
				<mu1 value="1.0"/>
				<mu2 value="1.0"/>
				<slip1 value="0.01"/>
				<slip2 value="0.01"/>
			</gazebo>
			<geometry>
				<box size="2.000000e-03 5.300000e-02 5.300000e-02"/>
			</geometry>
		</collision>
		<inertial>
			<origin xyz="1.015000e-02 0.000000e+00 0.000000e+00" rpy="0.000000e+00 -0.000000e+00 0.000000e+00"/>
			<mass value="0.058"/>
			<inertia ixx="1.460362666666667e-05" ixy="0.0" ixz="0.0" iyy="1.836130166666667e-05" iyz="0.0" izz="2.909826166666667e-05"/>
		</inertial>
	</link>
	<link name="LFFFRRF_Leg">
		<origin xyz="1.840399e-02 0.000000e+00 0.000000e+00" rpy="0.000000e+00 -0.000000e+00 0.000000e+00"/>
		<visual name="component_LFFFRRF_ActiveHinge__servo_visual">
			<origin xyz="2.990000e-02 0.000000e+00 0.000000e+00" rpy="0.000000e+00 -0.000000e+00 0.000000e+00"/>
			<material name="no_texture">
				<color rgba="0.7 0 0 1.0"/>
			</material>
			<geometry>
				<mesh filename="package://models/rg_robot/meshes/ActiveCardanHinge_Servo_Holder.dae"/>
			</geometry>
		</visual>
		<collision name="component_LFFFRRF_ActiveHinge__servo_collision">
			<origin xyz="1.015000e-02 0.000000e+00 0.000000e+00" rpy="0.000000e+00 -0.000000e+00 0.000000e+00"/>
			<contact>
				<lateral_friction value="0.8"/>
				<rolling_friction value="0"/>
				<spinning_friction value="1"/>
				<stiffness value="90000"/>
				<damping value="3333333.3333333335"/>
			</contact>
			<gazebo name="component_LFFFRRF_ActiveHinge__servo">
				<mu1 value="1.0"/>
				<mu2 value="1.0"/>
				<slip1 value="0.01"/>
				<slip2 value="0.01"/>
			</gazebo>
			<geometry>
				<box size="5.830000e-02 5.120000e-02 2.000000e-02"/>
			</geometry>
		</collision>
		<collision name="component_LFFFRRF_ActiveHinge__servo2_collision">
			<origin xyz="3.830000e-02 0.000000e+00 0.000000e+00" rpy="0.000000e+00 -0.000000e+00 0.000000e+00"/>
			<contact>
				<lateral_friction value="0.8"/>
				<rolling_friction value="0"/>
				<spinning_friction value="1"/>
				<stiffness value="90000"/>
				<damping value="3333333.3333333335"/>
			</contact>
			<gazebo name="component_LFFFRRF_ActiveHinge__servo2">
				<mu1 value="1.0"/>
				<mu2 value="1.0"/>
				<slip1 value="0.01"/>
				<slip2 value="0.01"/>
			</gazebo>
			<geometry>
				<box size="2.000000e-03 5.300000e-02 5.300000e-02"/>
			</geometry>
		</collision>
		<visual name="component_LFFFRRFF_ActiveHinge__frame_visual">
			<origin xyz="6.192500e-02 0.000000e+00 0.000000e+00" rpy="0.000000e+00 -0.000000e+00 0.000000e+00"/>
			<material name="no_texture">
				<color rgba="0.7 0 0 1.0"/>
			</material>
			<geometry>
				<mesh filename="package://models/rg_robot/meshes/ActiveHinge_Frame.dae"/>
			</geometry>
		</visual>
		<collision name="component_LFFFRRFF_ActiveHinge__frame_collision">
			<origin xyz="6.192500e-02 0.000000e+00 0.000000e+00" rpy="0.000000e+00 -0.000000e+00 0.000000e+00"/>
			<contact>
				<lateral_friction value="0.8"/>
				<rolling_friction value="0"/>
				<spinning_friction value="1"/>
				<stiffness value="90000"/>
				<damping value="3333333.3333333335"/>
			</contact>
			<gazebo name="component_LFFFRRFF_ActiveHinge__frame">
				<mu1 value="1.0"/>
				<mu2 value="1.0"/>
				<slip1 value="0.01"/>
				<slip2 value="0.01"/>
			</gazebo>
			<geometry>
				<box size="4.525000e-02 5.300000e-02 1.658910e-02"/>
			</geometry>
		</collision>
		<inertial>
			<origin xyz="1.840399e-02 0.000000e+00 0.000000e+00" rpy="0.000000e+00 -0.000000e+00 0.000000e+00"/>
			<mass value="0.069"/>
			<inertia ixx="1.7430808385575836e-05" ixy="0.0" ixz="0.0" iyy="4.5276804789561346e-05" iyz="0.0" izz="5.83364164039855e-05"/>
		</inertial>
	</link>
	<link name="LFFFRRFF_Leg">
		<origin xyz="1.015000e-02 0.000000e+00 0.000000e+00" rpy="0.000000e+00 -0.000000e+00 0.000000e+00"/>
		<visual name="component_LFFFRRFF_ActiveHinge__servo_visual">
			<origin xyz="2.990000e-02 0.000000e+00 0.000000e+00" rpy="0.000000e+00 -0.000000e+00 0.000000e+00"/>
			<material name="no_texture">
				<color rgba="0.7 0 0 1.0"/>
			</material>
			<geometry>
				<mesh filename="package://models/rg_robot/meshes/ActiveCardanHinge_Servo_Holder.dae"/>
			</geometry>
		</visual>
		<collision name="component_LFFFRRFF_ActiveHinge__servo_collision">
			<origin xyz="1.015000e-02 0.000000e+00 0.000000e+00" rpy="0.000000e+00 -0.000000e+00 0.000000e+00"/>
			<contact>
				<lateral_friction value="0.8"/>
				<rolling_friction value="0"/>
				<spinning_friction value="1"/>
				<stiffness value="90000"/>
				<damping value="3333333.3333333335"/>
			</contact>
			<gazebo name="component_LFFFRRFF_ActiveHinge__servo">
				<mu1 value="1.0"/>
				<mu2 value="1.0"/>
				<slip1 value="0.01"/>
				<slip2 value="0.01"/>
			</gazebo>
			<geometry>
				<box size="5.830000e-02 5.120000e-02 2.000000e-02"/>
			</geometry>
		</collision>
		<collision name="component_LFFFRRFF_ActiveHinge__servo2_collision">
			<origin xyz="3.830000e-02 0.000000e+00 0.000000e+00" rpy="0.000000e+00 -0.000000e+00 0.000000e+00"/>
			<contact>
				<lateral_friction value="0.8"/>
				<rolling_friction value="0"/>
				<spinning_friction value="1"/>
				<stiffness value="90000"/>
				<damping value="3333333.3333333335"/>
			</contact>
			<gazebo name="component_LFFFRRFF_ActiveHinge__servo2">
				<mu1 value="1.0"/>
				<mu2 value="1.0"/>
				<slip1 value="0.01"/>
				<slip2 value="0.01"/>
			</gazebo>
			<geometry>
				<box size="2.000000e-03 5.300000e-02 5.300000e-02"/>
			</geometry>
		</collision>
		<inertial>
			<origin xyz="1.015000e-02 0.000000e+00 0.000000e+00" rpy="0.000000e+00 -0.000000e+00 0.000000e+00"/>
			<mass value="0.058"/>
			<inertia ixx="1.460362666666667e-05" ixy="0.0" ixz="0.0" iyy="1.836130166666667e-05" iyz="0.0" izz="2.909826166666667e-05"/>
		</inertial>
	</link>
	<link name="LFFFL_Leg">
		<origin xyz="1.015000e-02 0.000000e+00 0.000000e+00" rpy="0.000000e+00 -0.000000e+00 0.000000e+00"/>
		<visual name="component_LFFFL_ActiveHinge__servo_visual">
			<origin xyz="2.990000e-02 0.000000e+00 0.000000e+00" rpy="0.000000e+00 -0.000000e+00 0.000000e+00"/>
			<material name="no_texture">
				<color rgba="1 0.08 0.58 1.0"/>
			</material>
			<geometry>
				<mesh filename="package://models/rg_robot/meshes/ActiveCardanHinge_Servo_Holder.dae"/>
			</geometry>
		</visual>
		<collision name="component_LFFFL_ActiveHinge__servo_collision">
			<origin xyz="1.015000e-02 0.000000e+00 0.000000e+00" rpy="0.000000e+00 -0.000000e+00 0.000000e+00"/>
			<contact>
				<lateral_friction value="0.8"/>
				<rolling_friction value="0"/>
				<spinning_friction value="1"/>
				<stiffness value="90000"/>
				<damping value="3333333.3333333335"/>
			</contact>
			<gazebo name="component_LFFFL_ActiveHinge__servo">
				<mu1 value="1.0"/>
				<mu2 value="1.0"/>
				<slip1 value="0.01"/>
				<slip2 value="0.01"/>
			</gazebo>
			<geometry>
				<box size="5.830000e-02 5.120000e-02 2.000000e-02"/>
			</geometry>
		</collision>
		<collision name="component_LFFFL_ActiveHinge__servo2_collision">
			<origin xyz="3.830000e-02 0.000000e+00 0.000000e+00" rpy="0.000000e+00 -0.000000e+00 0.000000e+00"/>
			<contact>
				<lateral_friction value="0.8"/>
				<rolling_friction value="0"/>
				<spinning_friction value="1"/>
				<stiffness value="90000"/>
				<damping value="3333333.3333333335"/>
			</contact>
			<gazebo name="component_LFFFL_ActiveHinge__servo2">
				<mu1 value="1.0"/>
				<mu2 value="1.0"/>
				<slip1 value="0.01"/>
				<slip2 value="0.01"/>
			</gazebo>
			<geometry>
				<box size="2.000000e-03 5.300000e-02 5.300000e-02"/>
			</geometry>
		</collision>
		<inertial>
			<origin xyz="1.015000e-02 0.000000e+00 0.000000e+00" rpy="0.000000e+00 -0.000000e+00 0.000000e+00"/>
			<mass value="0.058"/>
			<inertia ixx="1.460362666666667e-05" ixy="0.0" ixz="0.0" iyy="1.836130166666667e-05" iyz="0.0" izz="2.909826166666667e-05"/>
		</inertial>
	</link>
	<gazebo>
		<plugin name="robot_controller" filename="libRobotControlPlugin.so">
			<rv:robot_config xmlns:rv="https://github.com/ci-group/revolve">
				<rv:update_rate>8.000000e+00</rv:update_rate>
				<rv:brain>
					<rv:learner type="de" subtype="revde" CR="0.9" F="0.5" n_parents="3" verbose="false" population_size="20" max_eval="300"/>
					<rv:learner type="de" subtype="revde" CR="0.9" F="0.5" n_parents="3" verbose="false" population_size="20" max_eval="300"/>
					<rv:IMC active="false" restore_checkpoint="false" save_checkpoint="true" learning_rate="5e-2;" beta1="0.9;" beta2="0.99;" weight_decay="0.001;"/>
					<rv:sensors>
						<rv:sensor link="Core" sensor="core-imu_sensor" type="imu" id="Core_sensor" part_id="1"/>
					</rv:sensors>
					<rv:actuators>
						<rv:servomotor type="position" id="3__rotate" part_id="3" part_name="component_F_ActiveHinge__joint" joint="component_F_ActiveHinge__joint" coordinates="1.0;0.0;0.0">
							<rv:pid>
								<rv:p>1.000000e+00</rv:p>
								<rv:i>0.000000e+00</rv:i>
								<rv:d>0.000000e+00</rv:d>
								<rv:i_max>0.000000e+00</rv:i_max>
								<rv:i_min>0.000000e+00</rv:i_min>
							</rv:pid>
						</rv:servomotor>
						<rv:servomotor type="position" id="2__rotate" part_id="2" part_name="component_L_ActiveHinge__joint" joint="component_L_ActiveHinge__joint" coordinates="0.0;-1.0;0.0">
							<rv:pid>
								<rv:p>1.000000e+00</rv:p>
								<rv:i>0.000000e+00</rv:i>
								<rv:d>0.000000e+00</rv:d>
								<rv:i_max>0.000000e+00</rv:i_max>
								<rv:i_min>0.000000e+00</rv:i_min>
							</rv:pid>
						</rv:servomotor>
						<rv:servomotor type="position" id="4__rotate" part_id="4" part_name="component_LF_ActiveHinge__joint" joint="component_LF_ActiveHinge__joint" coordinates="0.0;-2.0;0.0">
							<rv:pid>
								<rv:p>1.000000e+00</rv:p>
								<rv:i>0.000000e+00</rv:i>
								<rv:d>0.000000e+00</rv:d>
								<rv:i_max>0.000000e+00</rv:i_max>
								<rv:i_min>0.000000e+00</rv:i_min>
							</rv:pid>
						</rv:servomotor>
						<rv:servomotor type="position" id="5__rotate" part_id="5" part_name="component_LFF_ActiveHinge__joint" joint="component_LFF_ActiveHinge__joint" coordinates="0.0;-3.0;0.0">
							<rv:pid>
								<rv:p>1.000000e+00</rv:p>
								<rv:i>0.000000e+00</rv:i>
								<rv:d>0.000000e+00</rv:d>
								<rv:i_max>0.000000e+00</rv:i_max>
								<rv:i_min>0.000000e+00</rv:i_min>
							</rv:pid>
						</rv:servomotor>
						<rv:servomotor type="position" id="10__rotate" part_id="10" part_name="component_LFFFRFR_ActiveHinge__joint" joint="component_LFFFRFR_ActiveHinge__joint" coordinates="2.0;-3.0;0.0">
							<rv:pid>
								<rv:p>1.000000e+00</rv:p>
								<rv:i>0.000000e+00</rv:i>
								<rv:d>0.000000e+00</rv:d>
								<rv:i_max>0.000000e+00</rv:i_max>
								<rv:i_min>0.000000e+00</rv:i_min>
							</rv:pid>
						</rv:servomotor>
						<rv:servomotor type="position" id="11__rotate" part_id="11" part_name="component_LFFFRFL_ActiveHinge__joint" joint="component_LFFFRFL_ActiveHinge__joint" coordinates="2.0;-5.0;0.0">
							<rv:pid>
								<rv:p>1.000000e+00</rv:p>
								<rv:i>0.000000e+00</rv:i>
								<rv:d>0.000000e+00</rv:d>
								<rv:i_max>0.000000e+00</rv:i_max>
								<rv:i_min>0.000000e+00</rv:i_min>
							</rv:pid>
						</rv:servomotor>
						<rv:servomotor type="position" id="13__rotate" part_id="13" part_name="component_LFFFRRF_ActiveHinge__joint" joint="component_LFFFRRF_ActiveHinge__joint" coordinates="1.0;-2.0;0.0">
							<rv:pid>
								<rv:p>1.000000e+00</rv:p>
								<rv:i>0.000000e+00</rv:i>
								<rv:d>0.000000e+00</rv:d>
								<rv:i_max>0.000000e+00</rv:i_max>
								<rv:i_min>0.000000e+00</rv:i_min>
							</rv:pid>
						</rv:servomotor>
						<rv:servomotor type="position" id="14__rotate" part_id="14" part_name="component_LFFFRRFF_ActiveHinge__joint" joint="component_LFFFRRFF_ActiveHinge__joint" coordinates="1.0;-1.0;0.0">
							<rv:pid>
								<rv:p>1.000000e+00</rv:p>
								<rv:i>0.000000e+00</rv:i>
								<rv:d>0.000000e+00</rv:d>
								<rv:i_max>0.000000e+00</rv:i_max>
								<rv:i_min>0.000000e+00</rv:i_min>
							</rv:pid>
						</rv:servomotor>
						<rv:servomotor type="position" id="8__rotate" part_id="8" part_name="component_LFFFL_ActiveHinge__joint" joint="component_LFFFL_ActiveHinge__joint" coordinates="-1.0;-4.0;0.0">
							<rv:pid>
								<rv:p>1.000000e+00</rv:p>
								<rv:i>0.000000e+00</rv:i>
								<rv:d>0.000000e+00</rv:d>
								<rv:i_max>0.000000e+00</rv:i_max>
								<rv:i_min>0.000000e+00</rv:i_min>
							</rv:pid>
						</rv:servomotor>
					</rv:actuators>
				</rv:brain>
			</rv:robot_config>
		</plugin>
	</gazebo>
</robot>
