<?xml version="1.0" ?>
<robot name="tinlicker">
	<origin xyz="0.000000e+00 0.000000e+00 2.500000e-01" rpy="0.000000e+00 -0.000000e+00 0.000000e+00"/>
	<joint name="component_L_ActiveHinge__joint" type="revolute">
		<origin xyz="-7.800000e-02 0.000000e+00 0.000000e+00" rpy="1.570796e+00 -0.000000e+00 3.141593e+00"/>
		<parent link="Core"/>
		<child link="L_Leg"/>
		<axis xyz="0.000000e+00 1.000000e+00 0.000000e+00"/>
		<use_parent_model_frame>0</use_parent_model_frame>
		<limit lower="-1.5707963267948966" upper="1.5707963267948966" effort="0.9212" velocity="5.235988"/>
	</joint>
	<joint name="component_LF_ActiveHinge__joint" type="revolute">
		<origin xyz="7.280000e-02 0.000000e+00 0.000000e+00" rpy="0.000000e+00 -0.000000e+00 0.000000e+00"/>
		<parent link="L_Leg"/>
		<child link="LF_Leg"/>
		<axis xyz="0.000000e+00 1.000000e+00 0.000000e+00"/>
		<use_parent_model_frame>0</use_parent_model_frame>
		<limit lower="-1.5707963267948966" upper="1.5707963267948966" effort="0.9212" velocity="5.235988"/>
	</joint>
	<joint name="component_LFF_ActiveHinge__joint" type="revolute">
		<origin xyz="7.280000e-02 0.000000e+00 0.000000e+00" rpy="0.000000e+00 -0.000000e+00 0.000000e+00"/>
		<parent link="LF_Leg"/>
		<child link="LFF_Leg"/>
		<axis xyz="0.000000e+00 1.000000e+00 0.000000e+00"/>
		<use_parent_model_frame>0</use_parent_model_frame>
		<limit lower="-1.5707963267948966" upper="1.5707963267948966" effort="0.9212" velocity="5.235988"/>
	</joint>
	<joint name="component_LFFF_ActiveHinge__joint" type="revolute">
		<origin xyz="7.280000e-02 0.000000e+00 0.000000e+00" rpy="-1.570796e+00 0.000000e+00 0.000000e+00"/>
		<parent link="LFF_Leg"/>
		<child link="LFFF_Leg"/>
		<axis xyz="0.000000e+00 1.000000e+00 0.000000e+00"/>
		<use_parent_model_frame>0</use_parent_model_frame>
		<limit lower="-1.5707963267948966" upper="1.5707963267948966" effort="0.9212" velocity="5.235988"/>
	</joint>
	<joint name="component_LFFFFLF_ActiveHinge__joint" type="revolute">
		<origin xyz="7.074313e-02 1.278294e-01 -1.859624e-18" rpy="1.570796e+00 5.551115e-17 1.570796e+00"/>
		<parent link="LFFF_Leg"/>
		<child link="LFFFFLF_Leg"/>
		<axis xyz="0.000000e+00 1.000000e+00 0.000000e+00"/>
		<use_parent_model_frame>0</use_parent_model_frame>
		<limit lower="-1.5707963267948966" upper="1.5707963267948966" effort="0.9212" velocity="5.235988"/>
	</joint>
	<joint name="component_LFFFFLRF_ActiveHinge__joint" type="revolute">
		<origin xyz="1.985725e-01 6.288625e-02 0.000000e+00" rpy="0.000000e+00 -0.000000e+00 0.000000e+00"/>
		<parent link="LFFF_Leg"/>
		<child link="LFFFFLRF_Leg"/>
		<axis xyz="0.000000e+00 1.000000e+00 0.000000e+00"/>
		<use_parent_model_frame>0</use_parent_model_frame>
		<limit lower="-1.5707963267948966" upper="1.5707963267948966" effort="0.9212" velocity="5.235988"/>
	</joint>
	<joint name="component_LFFFFLRFFF_ActiveHinge__joint" type="revolute">
		<origin xyz="1.356863e-01 0.000000e+00 0.000000e+00" rpy="1.570796e+00 -0.000000e+00 -0.000000e+00"/>
		<parent link="LFFFFLRF_Leg"/>
		<child link="LFFFFLRFFF_Leg"/>
		<axis xyz="0.000000e+00 1.000000e+00 0.000000e+00"/>
		<use_parent_model_frame>0</use_parent_model_frame>
		<limit lower="-1.5707963267948966" upper="1.5707963267948966" effort="0.9212" velocity="5.235988"/>
	</joint>
	<joint name="component_LFFFFLRFFRR_ActiveHinge__joint" type="revolute">
		<origin xyz="5.800000e-03 -6.288625e-02 0.000000e+00" rpy="1.570796e+00 -0.000000e+00 3.141593e+00"/>
		<parent link="LFFFFLRF_Leg"/>
		<child link="LFFFFLRFFRR_Leg"/>
		<axis xyz="0.000000e+00 1.000000e+00 0.000000e+00"/>
		<use_parent_model_frame>0</use_parent_model_frame>
		<limit lower="-1.5707963267948966" upper="1.5707963267948966" effort="0.9212" velocity="5.235988"/>
	</joint>
	<link name="Core">
		<origin xyz="-2.829023e-03 0.000000e+00 0.000000e+00" rpy="0.000000e+00 -0.000000e+00 0.000000e+00"/>
		<sensor name="core-imu_sensor" type="imu">
			<origin xyz="0.000000e+00 0.000000e+00 0.000000e+00" rpy="0.000000e+00 -0.000000e+00 0.000000e+00"/>
			<always_on>True</always_on>
		</sensor>
		<visual name="component__CoreComponent__box_visual">
			<origin xyz="0.000000e+00 0.000000e+00 0.000000e+00" rpy="0.000000e+00 -0.000000e+00 0.000000e+00"/>
			<material name="no_texture">
				<color rgba="1 1 0 1.0"/>
			</material>
			<geometry>
				<mesh filename="package://models/rg_robot/meshes/CoreComponent.dae"/>
			</geometry>
		</visual>
		<collision name="component__CoreComponent__box_collision">
			<origin xyz="0.000000e+00 0.000000e+00 0.000000e+00" rpy="0.000000e+00 -0.000000e+00 0.000000e+00"/>
			<contact>
				<lateral_friction value="0.8"/>
				<rolling_friction value="0"/>
				<spinning_friction value="1"/>
				<stiffness value="90000"/>
				<damping value="3333333.3333333335"/>
			</contact>
			<gazebo name="component__CoreComponent__box">
				<mu1 value="1.0"/>
				<mu2 value="1.0"/>
				<slip1 value="0.01"/>
				<slip2 value="0.01"/>
			</gazebo>
			<geometry>
				<box size="8.900000e-02 8.900000e-02 6.030000e-02"/>
			</geometry>
		</collision>
		<visual name="component_L_ActiveHinge__frame_visual">
			<origin xyz="-6.712500e-02 0.000000e+00 0.000000e+00" rpy="1.570796e+00 -0.000000e+00 3.141593e+00"/>
			<material name="no_texture">
				<color rgba="0.7 0 0 1.0"/>
			</material>
			<geometry>
				<mesh filename="package://models/rg_robot/meshes/ActiveHinge_Frame.dae"/>
			</geometry>
		</visual>
		<collision name="component_L_ActiveHinge__frame_collision">
			<origin xyz="-6.712500e-02 0.000000e+00 0.000000e+00" rpy="1.570796e+00 -0.000000e+00 3.141593e+00"/>
			<contact>
				<lateral_friction value="0.8"/>
				<rolling_friction value="0"/>
				<spinning_friction value="1"/>
				<stiffness value="90000"/>
				<damping value="3333333.3333333335"/>
			</contact>
			<gazebo name="component_L_ActiveHinge__frame">
				<mu1 value="1.0"/>
				<mu2 value="1.0"/>
				<slip1 value="0.01"/>
				<slip2 value="0.01"/>
			</gazebo>
			<geometry>
				<box size="4.525000e-02 5.300000e-02 1.658910e-02"/>
			</geometry>
		</collision>
		<inertial>
			<origin xyz="-2.829023e-03 0.000000e+00 0.000000e+00" rpy="0.000000e+00 -0.000000e+00 0.000000e+00"/>
			<mass value="0.261"/>
			<inertia ixx="0.00024359989005224246" ixy="0.0" ixz="0.0" iyy="0.0002926990993175287" iyz="0.0" izz="0.0003796454060364379"/>
		</inertial>
	</link>
	<link name="L_Leg">
		<origin xyz="1.840399e-02 0.000000e+00 0.000000e+00" rpy="0.000000e+00 -0.000000e+00 0.000000e+00"/>
		<visual name="component_L_ActiveHinge__servo_visual">
			<origin xyz="2.990000e-02 0.000000e+00 0.000000e+00" rpy="0.000000e+00 -0.000000e+00 0.000000e+00"/>
			<material name="no_texture">
				<color rgba="0.7 0 0 1.0"/>
			</material>
			<geometry>
				<mesh filename="package://models/rg_robot/meshes/ActiveCardanHinge_Servo_Holder.dae"/>
			</geometry>
		</visual>
		<collision name="component_L_ActiveHinge__servo_collision">
			<origin xyz="1.015000e-02 0.000000e+00 0.000000e+00" rpy="0.000000e+00 -0.000000e+00 0.000000e+00"/>
			<contact>
				<lateral_friction value="0.8"/>
				<rolling_friction value="0"/>
				<spinning_friction value="1"/>
				<stiffness value="90000"/>
				<damping value="3333333.3333333335"/>
			</contact>
			<gazebo name="component_L_ActiveHinge__servo">
				<mu1 value="1.0"/>
				<mu2 value="1.0"/>
				<slip1 value="0.01"/>
				<slip2 value="0.01"/>
			</gazebo>
			<geometry>
				<box size="5.830000e-02 5.120000e-02 2.000000e-02"/>
			</geometry>
		</collision>
		<collision name="component_L_ActiveHinge__servo2_collision">
			<origin xyz="3.830000e-02 0.000000e+00 0.000000e+00" rpy="0.000000e+00 -0.000000e+00 0.000000e+00"/>
			<contact>
				<lateral_friction value="0.8"/>
				<rolling_friction value="0"/>
				<spinning_friction value="1"/>
				<stiffness value="90000"/>
				<damping value="3333333.3333333335"/>
			</contact>
			<gazebo name="component_L_ActiveHinge__servo2">
				<mu1 value="1.0"/>
				<mu2 value="1.0"/>
				<slip1 value="0.01"/>
				<slip2 value="0.01"/>
			</gazebo>
			<geometry>
				<box size="2.000000e-03 5.300000e-02 5.300000e-02"/>
			</geometry>
		</collision>
		<visual name="component_LF_ActiveHinge__frame_visual">
			<origin xyz="6.192500e-02 0.000000e+00 0.000000e+00" rpy="0.000000e+00 -0.000000e+00 0.000000e+00"/>
			<material name="no_texture">
				<color rgba="0.7 0 0 1.0"/>
			</material>
			<geometry>
				<mesh filename="package://models/rg_robot/meshes/ActiveHinge_Frame.dae"/>
			</geometry>
		</visual>
		<collision name="component_LF_ActiveHinge__frame_collision">
			<origin xyz="6.192500e-02 0.000000e+00 0.000000e+00" rpy="0.000000e+00 -0.000000e+00 0.000000e+00"/>
			<contact>
				<lateral_friction value="0.8"/>
				<rolling_friction value="0"/>
				<spinning_friction value="1"/>
				<stiffness value="90000"/>
				<damping value="3333333.3333333335"/>
			</contact>
			<gazebo name="component_LF_ActiveHinge__frame">
				<mu1 value="1.0"/>
				<mu2 value="1.0"/>
				<slip1 value="0.01"/>
				<slip2 value="0.01"/>
			</gazebo>
			<geometry>
				<box size="4.525000e-02 5.300000e-02 1.658910e-02"/>
			</geometry>
		</collision>
		<inertial>
			<origin xyz="1.840399e-02 0.000000e+00 0.000000e+00" rpy="0.000000e+00 -0.000000e+00 0.000000e+00"/>
			<mass value="0.069"/>
			<inertia ixx="1.7430808385575836e-05" ixy="0.0" ixz="0.0" iyy="4.5276804789561346e-05" iyz="0.0" izz="5.83364164039855e-05"/>
		</inertial>
	</link>
	<link name="LF_Leg">
		<origin xyz="1.840399e-02 0.000000e+00 0.000000e+00" rpy="0.000000e+00 -0.000000e+00 0.000000e+00"/>
		<visual name="component_LF_ActiveHinge__servo_visual">
			<origin xyz="2.990000e-02 0.000000e+00 0.000000e+00" rpy="0.000000e+00 -0.000000e+00 0.000000e+00"/>
			<material name="no_texture">
				<color rgba="0.7 0 0 1.0"/>
			</material>
			<geometry>
				<mesh filename="package://models/rg_robot/meshes/ActiveCardanHinge_Servo_Holder.dae"/>
			</geometry>
		</visual>
		<collision name="component_LF_ActiveHinge__servo_collision">
			<origin xyz="1.015000e-02 0.000000e+00 0.000000e+00" rpy="0.000000e+00 -0.000000e+00 0.000000e+00"/>
			<contact>
				<lateral_friction value="0.8"/>
				<rolling_friction value="0"/>
				<spinning_friction value="1"/>
				<stiffness value="90000"/>
				<damping value="3333333.3333333335"/>
			</contact>
			<gazebo name="component_LF_ActiveHinge__servo">
				<mu1 value="1.0"/>
				<mu2 value="1.0"/>
				<slip1 value="0.01"/>
				<slip2 value="0.01"/>
			</gazebo>
			<geometry>
				<box size="5.830000e-02 5.120000e-02 2.000000e-02"/>
			</geometry>
		</collision>
		<collision name="component_LF_ActiveHinge__servo2_collision">
			<origin xyz="3.830000e-02 0.000000e+00 0.000000e+00" rpy="0.000000e+00 -0.000000e+00 0.000000e+00"/>
			<contact>
				<lateral_friction value="0.8"/>
				<rolling_friction value="0"/>
				<spinning_friction value="1"/>
				<stiffness value="90000"/>
				<damping value="3333333.3333333335"/>
			</contact>
			<gazebo name="component_LF_ActiveHinge__servo2">
				<mu1 value="1.0"/>
				<mu2 value="1.0"/>
				<slip1 value="0.01"/>
				<slip2 value="0.01"/>
			</gazebo>
			<geometry>
				<box size="2.000000e-03 5.300000e-02 5.300000e-02"/>
			</geometry>
		</collision>
		<visual name="component_LFF_ActiveHinge__frame_visual">
			<origin xyz="6.192500e-02 0.000000e+00 0.000000e+00" rpy="0.000000e+00 -0.000000e+00 0.000000e+00"/>
			<material name="no_texture">
				<color rgba="0.7 0 0 1.0"/>
			</material>
			<geometry>
				<mesh filename="package://models/rg_robot/meshes/ActiveHinge_Frame.dae"/>
			</geometry>
		</visual>
		<collision name="component_LFF_ActiveHinge__frame_collision">
			<origin xyz="6.192500e-02 0.000000e+00 0.000000e+00" rpy="0.000000e+00 -0.000000e+00 0.000000e+00"/>
			<contact>
				<lateral_friction value="0.8"/>
				<rolling_friction value="0"/>
				<spinning_friction value="1"/>
				<stiffness value="90000"/>
				<damping value="3333333.3333333335"/>
			</contact>
			<gazebo name="component_LFF_ActiveHinge__frame">
				<mu1 value="1.0"/>
				<mu2 value="1.0"/>
				<slip1 value="0.01"/>
				<slip2 value="0.01"/>
			</gazebo>
			<geometry>
				<box size="4.525000e-02 5.300000e-02 1.658910e-02"/>
			</geometry>
		</collision>
		<inertial>
			<origin xyz="1.840399e-02 0.000000e+00 0.000000e+00" rpy="0.000000e+00 -0.000000e+00 0.000000e+00"/>
			<mass value="0.069"/>
			<inertia ixx="1.7430808385575836e-05" ixy="0.0" ixz="0.0" iyy="4.5276804789561346e-05" iyz="0.0" izz="5.83364164039855e-05"/>
		</inertial>
	</link>
	<link name="LFF_Leg">
		<origin xyz="1.840399e-02 0.000000e+00 0.000000e+00" rpy="0.000000e+00 -0.000000e+00 0.000000e+00"/>
		<visual name="component_LFF_ActiveHinge__servo_visual">
			<origin xyz="2.990000e-02 0.000000e+00 0.000000e+00" rpy="0.000000e+00 -0.000000e+00 0.000000e+00"/>
			<material name="no_texture">
				<color rgba="0.7 0 0 1.0"/>
			</material>
			<geometry>
				<mesh filename="package://models/rg_robot/meshes/ActiveCardanHinge_Servo_Holder.dae"/>
			</geometry>
		</visual>
		<collision name="component_LFF_ActiveHinge__servo_collision">
			<origin xyz="1.015000e-02 0.000000e+00 0.000000e+00" rpy="0.000000e+00 -0.000000e+00 0.000000e+00"/>
			<contact>
				<lateral_friction value="0.8"/>
				<rolling_friction value="0"/>
				<spinning_friction value="1"/>
				<stiffness value="90000"/>
				<damping value="3333333.3333333335"/>
			</contact>
			<gazebo name="component_LFF_ActiveHinge__servo">
				<mu1 value="1.0"/>
				<mu2 value="1.0"/>
				<slip1 value="0.01"/>
				<slip2 value="0.01"/>
			</gazebo>
			<geometry>
				<box size="5.830000e-02 5.120000e-02 2.000000e-02"/>
			</geometry>
		</collision>
		<collision name="component_LFF_ActiveHinge__servo2_collision">
			<origin xyz="3.830000e-02 0.000000e+00 0.000000e+00" rpy="0.000000e+00 -0.000000e+00 0.000000e+00"/>
			<contact>
				<lateral_friction value="0.8"/>
				<rolling_friction value="0"/>
				<spinning_friction value="1"/>
				<stiffness value="90000"/>
				<damping value="3333333.3333333335"/>
			</contact>
			<gazebo name="component_LFF_ActiveHinge__servo2">
				<mu1 value="1.0"/>
				<mu2 value="1.0"/>
				<slip1 value="0.01"/>
				<slip2 value="0.01"/>
			</gazebo>
			<geometry>
				<box size="2.000000e-03 5.300000e-02 5.300000e-02"/>
			</geometry>
		</collision>
		<visual name="component_LFFF_ActiveHinge__frame_visual">
			<origin xyz="6.192500e-02 0.000000e+00 0.000000e+00" rpy="-1.570796e+00 0.000000e+00 0.000000e+00"/>
			<material name="no_texture">
				<color rgba="1 0.08 0.58 1.0"/>
			</material>
			<geometry>
				<mesh filename="package://models/rg_robot/meshes/ActiveHinge_Frame.dae"/>
			</geometry>
		</visual>
		<collision name="component_LFFF_ActiveHinge__frame_collision">
			<origin xyz="6.192500e-02 0.000000e+00 0.000000e+00" rpy="-1.570796e+00 0.000000e+00 0.000000e+00"/>
			<contact>
				<lateral_friction value="0.8"/>
				<rolling_friction value="0"/>
				<spinning_friction value="1"/>
				<stiffness value="90000"/>
				<damping value="3333333.3333333335"/>
			</contact>
			<gazebo name="component_LFFF_ActiveHinge__frame">
				<mu1 value="1.0"/>
				<mu2 value="1.0"/>
				<slip1 value="0.01"/>
				<slip2 value="0.01"/>
			</gazebo>
			<geometry>
				<box size="4.525000e-02 5.300000e-02 1.658910e-02"/>
			</geometry>
		</collision>
		<inertial>
			<origin xyz="1.840399e-02 0.000000e+00 0.000000e+00" rpy="0.000000e+00 -0.000000e+00 0.000000e+00"/>
			<mass value="0.069"/>
			<inertia ixx="1.7430808385575836e-05" ixy="0.0" ixz="0.0" iyy="4.759945640398551e-05" iyz="-1.0314645202066005e-21" izz="5.601376478956134e-05"/>
		</inertial>
	</link>
	<link name="LFFF_Leg">
		<origin xyz="7.846948e-02 4.762298e-02 -6.907669e-20" rpy="0.000000e+00 -0.000000e+00 0.000000e+00"/>
		<visual name="component_LFFF_ActiveHinge__servo_visual">
			<origin xyz="2.990000e-02 0.000000e+00 0.000000e+00" rpy="0.000000e+00 -0.000000e+00 0.000000e+00"/>
			<material name="no_texture">
				<color rgba="1 0.08 0.58 1.0"/>
			</material>
			<geometry>
				<mesh filename="package://models/rg_robot/meshes/ActiveCardanHinge_Servo_Holder.dae"/>
			</geometry>
		</visual>
		<collision name="component_LFFF_ActiveHinge__servo_collision">
			<origin xyz="1.015000e-02 0.000000e+00 0.000000e+00" rpy="0.000000e+00 -0.000000e+00 0.000000e+00"/>
			<contact>
				<lateral_friction value="0.8"/>
				<rolling_friction value="0"/>
				<spinning_friction value="1"/>
				<stiffness value="90000"/>
				<damping value="3333333.3333333335"/>
			</contact>
			<gazebo name="component_LFFF_ActiveHinge__servo">
				<mu1 value="1.0"/>
				<mu2 value="1.0"/>
				<slip1 value="0.01"/>
				<slip2 value="0.01"/>
			</gazebo>
			<geometry>
				<box size="5.830000e-02 5.120000e-02 2.000000e-02"/>
			</geometry>
		</collision>
		<collision name="component_LFFF_ActiveHinge__servo2_collision">
			<origin xyz="3.830000e-02 0.000000e+00 0.000000e+00" rpy="0.000000e+00 -0.000000e+00 0.000000e+00"/>
			<contact>
				<lateral_friction value="0.8"/>
				<rolling_friction value="0"/>
				<spinning_friction value="1"/>
				<stiffness value="90000"/>
				<damping value="3333333.3333333335"/>
			</contact>
			<gazebo name="component_LFFF_ActiveHinge__servo2">
				<mu1 value="1.0"/>
				<mu2 value="1.0"/>
				<slip1 value="0.01"/>
				<slip2 value="0.01"/>
			</gazebo>
			<geometry>
				<box size="2.000000e-03 5.300000e-02 5.300000e-02"/>
			</geometry>
		</collision>
		<visual name="component_LFFFF_FixedBrick__box_visual">
			<origin xyz="7.074313e-02 0.000000e+00 0.000000e+00" rpy="0.000000e+00 0.000000e+00 -1.570796e+00"/>
			<material name="no_texture">
				<color rgba="0 0 1 1.0"/>
			</material>
			<geometry>
				<mesh filename="package://models/rg_robot/meshes/FixedBrick.dae"/>
			</geometry>
		</visual>
		<collision name="component_LFFFF_FixedBrick__box_collision">
			<origin xyz="7.074313e-02 0.000000e+00 0.000000e+00" rpy="0.000000e+00 0.000000e+00 -1.570796e+00"/>
			<contact>
				<lateral_friction value="0.8"/>
				<rolling_friction value="0"/>
				<spinning_friction value="1"/>
				<stiffness value="90000"/>
				<damping value="3333333.3333333335"/>
			</contact>
			<gazebo name="component_LFFFF_FixedBrick__box">
				<mu1 value="1.0"/>
				<mu2 value="1.0"/>
				<slip1 value="0.01"/>
				<slip2 value="0.01"/>
			</gazebo>
			<geometry>
				<box size="6.288625e-02 6.288625e-02 6.030000e-02"/>
			</geometry>
		</collision>
		<visual name="component_LFFFFL_FixedBrick__box_visual">
			<origin xyz="7.074313e-02 6.288625e-02 0.000000e+00" rpy="0.000000e+00 -0.000000e+00 0.000000e+00"/>
			<material name="no_texture">
				<color rgba="0 0 1 1.0"/>
			</material>
			<geometry>
				<mesh filename="package://models/rg_robot/meshes/FixedBrick.dae"/>
			</geometry>
		</visual>
		<collision name="component_LFFFFL_FixedBrick__box_collision">
			<origin xyz="7.074313e-02 6.288625e-02 0.000000e+00" rpy="0.000000e+00 -0.000000e+00 0.000000e+00"/>
			<contact>
				<lateral_friction value="0.8"/>
				<rolling_friction value="0"/>
				<spinning_friction value="1"/>
				<stiffness value="90000"/>
				<damping value="3333333.3333333335"/>
			</contact>
			<gazebo name="component_LFFFFL_FixedBrick__box">
				<mu1 value="1.0"/>
				<mu2 value="1.0"/>
				<slip1 value="0.01"/>
				<slip2 value="0.01"/>
			</gazebo>
			<geometry>
				<box size="6.288625e-02 6.288625e-02 6.030000e-02"/>
			</geometry>
		</collision>
		<visual name="component_LFFFFLF_ActiveHinge__frame_visual">
			<origin xyz="7.074313e-02 1.169544e-01 -1.255940e-18" rpy="1.570796e+00 5.551115e-17 1.570796e+00"/>
			<material name="no_texture">
				<color rgba="0.7 0 0 1.0"/>
			</material>
			<geometry>
				<mesh filename="package://models/rg_robot/meshes/ActiveHinge_Frame.dae"/>
			</geometry>
		</visual>
		<collision name="component_LFFFFLF_ActiveHinge__frame_collision">
			<origin xyz="7.074313e-02 1.169544e-01 -1.255940e-18" rpy="1.570796e+00 5.551115e-17 1.570796e+00"/>
			<contact>
				<lateral_friction value="0.8"/>
				<rolling_friction value="0"/>
				<spinning_friction value="1"/>
				<stiffness value="90000"/>
				<damping value="3333333.3333333335"/>
			</contact>
			<gazebo name="component_LFFFFLF_ActiveHinge__frame">
				<mu1 value="1.0"/>
				<mu2 value="1.0"/>
				<slip1 value="0.01"/>
				<slip2 value="0.01"/>
			</gazebo>
			<geometry>
				<box size="4.525000e-02 5.300000e-02 1.658910e-02"/>
			</geometry>
		</collision>
		<visual name="component_LFFFFLR_FixedBrick__box_visual">
			<origin xyz="1.336294e-01 6.288625e-02 0.000000e+00" rpy="0.000000e+00 0.000000e+00 -1.570796e+00"/>
			<material name="no_texture">
				<color rgba="0 0 1 1.0"/>
			</material>
			<geometry>
				<mesh filename="package://models/rg_robot/meshes/FixedBrick.dae"/>
			</geometry>
		</visual>
		<collision name="component_LFFFFLR_FixedBrick__box_collision">
			<origin xyz="1.336294e-01 6.288625e-02 0.000000e+00" rpy="0.000000e+00 0.000000e+00 -1.570796e+00"/>
			<contact>
				<lateral_friction value="0.8"/>
				<rolling_friction value="0"/>
				<spinning_friction value="1"/>
				<stiffness value="90000"/>
				<damping value="3333333.3333333335"/>
			</contact>
			<gazebo name="component_LFFFFLR_FixedBrick__box">
				<mu1 value="1.0"/>
				<mu2 value="1.0"/>
				<slip1 value="0.01"/>
				<slip2 value="0.01"/>
			</gazebo>
			<geometry>
				<box size="6.288625e-02 6.288625e-02 6.030000e-02"/>
			</geometry>
		</collision>
		<visual name="component_LFFFFLRF_ActiveHinge__frame_visual">
			<origin xyz="1.876975e-01 6.288625e-02 0.000000e+00" rpy="0.000000e+00 -0.000000e+00 0.000000e+00"/>
			<material name="no_texture">
				<color rgba="1 0.08 0.58 1.0"/>
			</material>
			<geometry>
				<mesh filename="package://models/rg_robot/meshes/ActiveHinge_Frame.dae"/>
			</geometry>
		</visual>
		<collision name="component_LFFFFLRF_ActiveHinge__frame_collision">
			<origin xyz="1.876975e-01 6.288625e-02 0.000000e+00" rpy="0.000000e+00 -0.000000e+00 0.000000e+00"/>
			<contact>
				<lateral_friction value="0.8"/>
				<rolling_friction value="0"/>
				<spinning_friction value="1"/>
				<stiffness value="90000"/>
				<damping value="3333333.3333333335"/>
			</contact>
			<gazebo name="component_LFFFFLRF_ActiveHinge__frame">
				<mu1 value="1.0"/>
				<mu2 value="1.0"/>
				<slip1 value="0.01"/>
				<slip2 value="0.01"/>
			</gazebo>
			<geometry>
				<box size="4.525000e-02 5.300000e-02 1.658910e-02"/>
			</geometry>
		</collision>
		<visual name="component_LFFFFLRL_FixedBrick__box_visual">
			<origin xyz="1.336294e-01 1.257725e-01 0.000000e+00" rpy="0.000000e+00 -0.000000e+00 0.000000e+00"/>
			<material name="no_texture">
				<color rgba="0 0 1 1.0"/>
			</material>
			<geometry>
				<mesh filename="package://models/rg_robot/meshes/FixedBrick.dae"/>
			</geometry>
		</visual>
		<collision name="component_LFFFFLRL_FixedBrick__box_collision">
			<origin xyz="1.336294e-01 1.257725e-01 0.000000e+00" rpy="0.000000e+00 -0.000000e+00 0.000000e+00"/>
			<contact>
				<lateral_friction value="0.8"/>
				<rolling_friction value="0"/>
				<spinning_friction value="1"/>
				<stiffness value="90000"/>
				<damping value="3333333.3333333335"/>
			</contact>
			<gazebo name="component_LFFFFLRL_FixedBrick__box">
				<mu1 value="1.0"/>
				<mu2 value="1.0"/>
				<slip1 value="0.01"/>
				<slip2 value="0.01"/>
			</gazebo>
			<geometry>
				<box size="6.288625e-02 6.288625e-02 6.030000e-02"/>
			</geometry>
		</collision>
		<inertial>
			<origin xyz="7.846948e-02 4.762298e-02 -6.907669e-20" rpy="0.000000e+00 -0.000000e+00 0.000000e+00"/>
			<mass value="0.2"/>
			<inertia ixx="0.0005500061815872197" ixy="-0.0003632338238706543" ixz="1.2578271045081525e-21" iyy="0.0006879770240149831" iyz="1.5100616416376224e-21" izz="0.0011557403754977177"/>
		</inertial>
	</link>
	<link name="LFFFFLF_Leg">
		<origin xyz="1.015000e-02 0.000000e+00 0.000000e+00" rpy="0.000000e+00 -0.000000e+00 0.000000e+00"/>
		<visual name="component_LFFFFLF_ActiveHinge__servo_visual">
			<origin xyz="2.990000e-02 0.000000e+00 0.000000e+00" rpy="0.000000e+00 -0.000000e+00 0.000000e+00"/>
			<material name="no_texture">
				<color rgba="0.7 0 0 1.0"/>
			</material>
			<geometry>
				<mesh filename="package://models/rg_robot/meshes/ActiveCardanHinge_Servo_Holder.dae"/>
			</geometry>
		</visual>
		<collision name="component_LFFFFLF_ActiveHinge__servo_collision">
			<origin xyz="1.015000e-02 0.000000e+00 0.000000e+00" rpy="0.000000e+00 -0.000000e+00 0.000000e+00"/>
			<contact>
				<lateral_friction value="0.8"/>
				<rolling_friction value="0"/>
				<spinning_friction value="1"/>
				<stiffness value="90000"/>
				<damping value="3333333.3333333335"/>
			</contact>
			<gazebo name="component_LFFFFLF_ActiveHinge__servo">
				<mu1 value="1.0"/>
				<mu2 value="1.0"/>
				<slip1 value="0.01"/>
				<slip2 value="0.01"/>
			</gazebo>
			<geometry>
				<box size="5.830000e-02 5.120000e-02 2.000000e-02"/>
			</geometry>
		</collision>
		<collision name="component_LFFFFLF_ActiveHinge__servo2_collision">
			<origin xyz="3.830000e-02 0.000000e+00 0.000000e+00" rpy="0.000000e+00 -0.000000e+00 0.000000e+00"/>
			<contact>
				<lateral_friction value="0.8"/>
				<rolling_friction value="0"/>
				<spinning_friction value="1"/>
				<stiffness value="90000"/>
				<damping value="3333333.3333333335"/>
			</contact>
			<gazebo name="component_LFFFFLF_ActiveHinge__servo2">
				<mu1 value="1.0"/>
				<mu2 value="1.0"/>
				<slip1 value="0.01"/>
				<slip2 value="0.01"/>
			</gazebo>
			<geometry>
				<box size="2.000000e-03 5.300000e-02 5.300000e-02"/>
			</geometry>
		</collision>
		<inertial>
			<origin xyz="1.015000e-02 0.000000e+00 0.000000e+00" rpy="0.000000e+00 -0.000000e+00 0.000000e+00"/>
			<mass value="0.058"/>
			<inertia ixx="1.460362666666667e-05" ixy="0.0" ixz="0.0" iyy="1.836130166666667e-05" iyz="0.0" izz="2.909826166666667e-05"/>
		</inertial>
	</link>
	<link name="LFFFFLRF_Leg">
		<origin xyz="4.564026e-02 -1.841669e-02 0.000000e+00" rpy="0.000000e+00 -0.000000e+00 0.000000e+00"/>
		<visual name="component_LFFFFLRF_ActiveHinge__servo_visual">
			<origin xyz="2.990000e-02 0.000000e+00 0.000000e+00" rpy="0.000000e+00 -0.000000e+00 0.000000e+00"/>
			<material name="no_texture">
				<color rgba="1 0.08 0.58 1.0"/>
			</material>
			<geometry>
				<mesh filename="package://models/rg_robot/meshes/ActiveCardanHinge_Servo_Holder.dae"/>
			</geometry>
		</visual>
		<collision name="component_LFFFFLRF_ActiveHinge__servo_collision">
			<origin xyz="1.015000e-02 0.000000e+00 0.000000e+00" rpy="0.000000e+00 -0.000000e+00 0.000000e+00"/>
			<contact>
				<lateral_friction value="0.8"/>
				<rolling_friction value="0"/>
				<spinning_friction value="1"/>
				<stiffness value="90000"/>
				<damping value="3333333.3333333335"/>
			</contact>
			<gazebo name="component_LFFFFLRF_ActiveHinge__servo">
				<mu1 value="1.0"/>
				<mu2 value="1.0"/>
				<slip1 value="0.01"/>
				<slip2 value="0.01"/>
			</gazebo>
			<geometry>
				<box size="5.830000e-02 5.120000e-02 2.000000e-02"/>
			</geometry>
		</collision>
		<collision name="component_LFFFFLRF_ActiveHinge__servo2_collision">
			<origin xyz="3.830000e-02 0.000000e+00 0.000000e+00" rpy="0.000000e+00 -0.000000e+00 0.000000e+00"/>
			<contact>
				<lateral_friction value="0.8"/>
				<rolling_friction value="0"/>
				<spinning_friction value="1"/>
				<stiffness value="90000"/>
				<damping value="3333333.3333333335"/>
			</contact>
			<gazebo name="component_LFFFFLRF_ActiveHinge__servo2">
				<mu1 value="1.0"/>
				<mu2 value="1.0"/>
				<slip1 value="0.01"/>
				<slip2 value="0.01"/>
			</gazebo>
			<geometry>
				<box size="2.000000e-03 5.300000e-02 5.300000e-02"/>
			</geometry>
		</collision>
		<visual name="component_LFFFFLRFF_FixedBrick__box_visual">
			<origin xyz="7.074313e-02 0.000000e+00 0.000000e+00" rpy="0.000000e+00 0.000000e+00 -1.570796e+00"/>
			<material name="no_texture">
				<color rgba="0 0 1 1.0"/>
			</material>
			<geometry>
				<mesh filename="package://models/rg_robot/meshes/FixedBrick.dae"/>
			</geometry>
		</visual>
		<collision name="component_LFFFFLRFF_FixedBrick__box_collision">
			<origin xyz="7.074313e-02 0.000000e+00 0.000000e+00" rpy="0.000000e+00 0.000000e+00 -1.570796e+00"/>
			<contact>
				<lateral_friction value="0.8"/>
				<rolling_friction value="0"/>
				<spinning_friction value="1"/>
				<stiffness value="90000"/>
				<damping value="3333333.3333333335"/>
			</contact>
			<gazebo name="component_LFFFFLRFF_FixedBrick__box">
				<mu1 value="1.0"/>
				<mu2 value="1.0"/>
				<slip1 value="0.01"/>
				<slip2 value="0.01"/>
			</gazebo>
			<geometry>
				<box size="6.288625e-02 6.288625e-02 6.030000e-02"/>
			</geometry>
		</collision>
		<visual name="component_LFFFFLRFFF_ActiveHinge__frame_visual">
			<origin xyz="1.248113e-01 0.000000e+00 0.000000e+00" rpy="1.570796e+00 -0.000000e+00 -0.000000e+00"/>
			<material name="no_texture">
				<color rgba="0.7 0 0 1.0"/>
			</material>
			<geometry>
				<mesh filename="package://models/rg_robot/meshes/ActiveHinge_Frame.dae"/>
			</geometry>
		</visual>
		<collision name="component_LFFFFLRFFF_ActiveHinge__frame_collision">
			<origin xyz="1.248113e-01 0.000000e+00 0.000000e+00" rpy="1.570796e+00 -0.000000e+00 -0.000000e+00"/>
			<contact>
				<lateral_friction value="0.8"/>
				<rolling_friction value="0"/>
				<spinning_friction value="1"/>
				<stiffness value="90000"/>
				<damping value="3333333.3333333335"/>
			</contact>
			<gazebo name="component_LFFFFLRFFF_ActiveHinge__frame">
				<mu1 value="1.0"/>
				<mu2 value="1.0"/>
				<slip1 value="0.01"/>
				<slip2 value="0.01"/>
			</gazebo>
			<geometry>
				<box size="4.525000e-02 5.300000e-02 1.658910e-02"/>
			</geometry>
		</collision>
		<visual name="component_LFFFFLRFFR_FixedBrick__box_visual">
			<origin xyz="7.074313e-02 -6.288625e-02 0.000000e+00" rpy="0.000000e+00 -0.000000e+00 3.141593e+00"/>
			<material name="no_texture">
				<color rgba="0 0 1 1.0"/>
			</material>
			<geometry>
				<mesh filename="package://models/rg_robot/meshes/FixedBrick.dae"/>
			</geometry>
		</visual>
		<collision name="component_LFFFFLRFFR_FixedBrick__box_collision">
			<origin xyz="7.074313e-02 -6.288625e-02 0.000000e+00" rpy="0.000000e+00 -0.000000e+00 3.141593e+00"/>
			<contact>
				<lateral_friction value="0.8"/>
				<rolling_friction value="0"/>
				<spinning_friction value="1"/>
				<stiffness value="90000"/>
				<damping value="3333333.3333333335"/>
			</contact>
			<gazebo name="component_LFFFFLRFFR_FixedBrick__box">
				<mu1 value="1.0"/>
				<mu2 value="1.0"/>
				<slip1 value="0.01"/>
				<slip2 value="0.01"/>
			</gazebo>
			<geometry>
				<box size="6.288625e-02 6.288625e-02 6.030000e-02"/>
			</geometry>
		</collision>
		<visual name="component_LFFFFLRFFRR_ActiveHinge__frame_visual">
			<origin xyz="1.667500e-02 -6.288625e-02 0.000000e+00" rpy="1.570796e+00 -0.000000e+00 3.141593e+00"/>
			<material name="no_texture">
				<color rgba="0.7 0 0 1.0"/>
			</material>
			<geometry>
				<mesh filename="package://models/rg_robot/meshes/ActiveHinge_Frame.dae"/>
			</geometry>
		</visual>
		<collision name="component_LFFFFLRFFRR_ActiveHinge__frame_collision">
			<origin xyz="1.667500e-02 -6.288625e-02 0.000000e+00" rpy="1.570796e+00 -0.000000e+00 3.141593e+00"/>
			<contact>
				<lateral_friction value="0.8"/>
				<rolling_friction value="0"/>
				<spinning_friction value="1"/>
				<stiffness value="90000"/>
				<damping value="3333333.3333333335"/>
			</contact>
			<gazebo name="component_LFFFFLRFFRR_ActiveHinge__frame">
				<mu1 value="1.0"/>
				<mu2 value="1.0"/>
				<slip1 value="0.01"/>
				<slip2 value="0.01"/>
			</gazebo>
			<geometry>
				<box size="4.525000e-02 5.300000e-02 1.658910e-02"/>
			</geometry>
		</collision>
		<inertial>
			<origin xyz="4.564026e-02 -1.841669e-02 0.000000e+00" rpy="0.000000e+00 -0.000000e+00 0.000000e+00"/>
			<mass value="0.14"/>
			<inertia ixx="0.00017286932731518822" ixy="2.7322071687265635e-05" ixz="0.0" iyy="0.0002542598292223847" iyz="0.0" izz="0.00037660192320423957"/>
		</inertial>
	</link>
	<link name="LFFFFLRFFF_Leg">
		<origin xyz="1.015000e-02 0.000000e+00 0.000000e+00" rpy="0.000000e+00 -0.000000e+00 0.000000e+00"/>
		<visual name="component_LFFFFLRFFF_ActiveHinge__servo_visual">
			<origin xyz="2.990000e-02 0.000000e+00 0.000000e+00" rpy="0.000000e+00 -0.000000e+00 0.000000e+00"/>
			<material name="no_texture">
				<color rgba="0.7 0 0 1.0"/>
			</material>
			<geometry>
				<mesh filename="package://models/rg_robot/meshes/ActiveCardanHinge_Servo_Holder.dae"/>
			</geometry>
		</visual>
		<collision name="component_LFFFFLRFFF_ActiveHinge__servo_collision">
			<origin xyz="1.015000e-02 0.000000e+00 0.000000e+00" rpy="0.000000e+00 -0.000000e+00 0.000000e+00"/>
			<contact>
				<lateral_friction value="0.8"/>
				<rolling_friction value="0"/>
				<spinning_friction value="1"/>
				<stiffness value="90000"/>
				<damping value="3333333.3333333335"/>
			</contact>
			<gazebo name="component_LFFFFLRFFF_ActiveHinge__servo">
				<mu1 value="1.0"/>
				<mu2 value="1.0"/>
				<slip1 value="0.01"/>
				<slip2 value="0.01"/>
			</gazebo>
			<geometry>
				<box size="5.830000e-02 5.120000e-02 2.000000e-02"/>
			</geometry>
		</collision>
		<collision name="component_LFFFFLRFFF_ActiveHinge__servo2_collision">
			<origin xyz="3.830000e-02 0.000000e+00 0.000000e+00" rpy="0.000000e+00 -0.000000e+00 0.000000e+00"/>
			<contact>
				<lateral_friction value="0.8"/>
				<rolling_friction value="0"/>
				<spinning_friction value="1"/>
				<stiffness value="90000"/>
				<damping value="3333333.3333333335"/>
			</contact>
			<gazebo name="component_LFFFFLRFFF_ActiveHinge__servo2">
				<mu1 value="1.0"/>
				<mu2 value="1.0"/>
				<slip1 value="0.01"/>
				<slip2 value="0.01"/>
			</gazebo>
			<geometry>
				<box size="2.000000e-03 5.300000e-02 5.300000e-02"/>
			</geometry>
		</collision>
		<inertial>
			<origin xyz="1.015000e-02 0.000000e+00 0.000000e+00" rpy="0.000000e+00 -0.000000e+00 0.000000e+00"/>
			<mass value="0.058"/>
			<inertia ixx="1.460362666666667e-05" ixy="0.0" ixz="0.0" iyy="1.836130166666667e-05" iyz="0.0" izz="2.909826166666667e-05"/>
		</inertial>
	</link>
	<link name="LFFFFLRFFRR_Leg">
		<origin xyz="1.015000e-02 0.000000e+00 0.000000e+00" rpy="0.000000e+00 -0.000000e+00 0.000000e+00"/>
		<visual name="component_LFFFFLRFFRR_ActiveHinge__servo_visual">
			<origin xyz="2.990000e-02 0.000000e+00 0.000000e+00" rpy="0.000000e+00 -0.000000e+00 0.000000e+00"/>
			<material name="no_texture">
				<color rgba="0.7 0 0 1.0"/>
			</material>
			<geometry>
				<mesh filename="package://models/rg_robot/meshes/ActiveCardanHinge_Servo_Holder.dae"/>
			</geometry>
		</visual>
		<collision name="component_LFFFFLRFFRR_ActiveHinge__servo_collision">
			<origin xyz="1.015000e-02 0.000000e+00 0.000000e+00" rpy="0.000000e+00 -0.000000e+00 0.000000e+00"/>
			<contact>
				<lateral_friction value="0.8"/>
				<rolling_friction value="0"/>
				<spinning_friction value="1"/>
				<stiffness value="90000"/>
				<damping value="3333333.3333333335"/>
			</contact>
			<gazebo name="component_LFFFFLRFFRR_ActiveHinge__servo">
				<mu1 value="1.0"/>
				<mu2 value="1.0"/>
				<slip1 value="0.01"/>
				<slip2 value="0.01"/>
			</gazebo>
			<geometry>
				<box size="5.830000e-02 5.120000e-02 2.000000e-02"/>
			</geometry>
		</collision>
		<collision name="component_LFFFFLRFFRR_ActiveHinge__servo2_collision">
			<origin xyz="3.830000e-02 0.000000e+00 0.000000e+00" rpy="0.000000e+00 -0.000000e+00 0.000000e+00"/>
			<contact>
				<lateral_friction value="0.8"/>
				<rolling_friction value="0"/>
				<spinning_friction value="1"/>
				<stiffness value="90000"/>
				<damping value="3333333.3333333335"/>
			</contact>
			<gazebo name="component_LFFFFLRFFRR_ActiveHinge__servo2">
				<mu1 value="1.0"/>
				<mu2 value="1.0"/>
				<slip1 value="0.01"/>
				<slip2 value="0.01"/>
			</gazebo>
			<geometry>
				<box size="2.000000e-03 5.300000e-02 5.300000e-02"/>
			</geometry>
		</collision>
		<inertial>
			<origin xyz="1.015000e-02 0.000000e+00 0.000000e+00" rpy="0.000000e+00 -0.000000e+00 0.000000e+00"/>
			<mass value="0.058"/>
			<inertia ixx="1.460362666666667e-05" ixy="0.0" ixz="0.0" iyy="1.836130166666667e-05" iyz="0.0" izz="2.909826166666667e-05"/>
		</inertial>
	</link>
	<gazebo>
		<plugin name="robot_controller" filename="libRobotControlPlugin.so">
			<rv:robot_config xmlns:rv="https://github.com/ci-group/revolve">
				<rv:update_rate>8.000000e+00</rv:update_rate>
				<rv:brain>
					<rv:learner type="de" subtype="revde" CR="0.9" F="0.5" n_parents="3" verbose="false" population_size="20" max_eval="300"/>
					<rv:learner type="de" subtype="revde" CR="0.9" F="0.5" n_parents="3" verbose="false" population_size="20" max_eval="300"/>
					<rv:IMC active="false" restore_checkpoint="false" save_checkpoint="true" learning_rate="5e-2;" beta1="0.9;" beta2="0.99;" weight_decay="0.001;"/>
					<rv:sensors>
						<rv:sensor link="Core" sensor="core-imu_sensor" type="imu" id="Core_sensor" part_id="1"/>
					</rv:sensors>
					<rv:actuators>
						<rv:servomotor type="position" id="2__rotate" part_id="2" part_name="component_L_ActiveHinge__joint" joint="component_L_ActiveHinge__joint" coordinates="0.0;-1.0;0.0">
							<rv:pid>
								<rv:p>1.000000e+00</rv:p>
								<rv:i>0.000000e+00</rv:i>
								<rv:d>0.000000e+00</rv:d>
								<rv:i_max>0.000000e+00</rv:i_max>
								<rv:i_min>0.000000e+00</rv:i_min>
							</rv:pid>
						</rv:servomotor>
						<rv:servomotor type="position" id="3__rotate" part_id="3" part_name="component_LF_ActiveHinge__joint" joint="component_LF_ActiveHinge__joint" coordinates="0.0;-2.0;0.0">
							<rv:pid>
								<rv:p>1.000000e+00</rv:p>
								<rv:i>0.000000e+00</rv:i>
								<rv:d>0.000000e+00</rv:d>
								<rv:i_max>0.000000e+00</rv:i_max>
								<rv:i_min>0.000000e+00</rv:i_min>
							</rv:pid>
						</rv:servomotor>
						<rv:servomotor type="position" id="4__rotate" part_id="4" part_name="component_LFF_ActiveHinge__joint" joint="component_LFF_ActiveHinge__joint" coordinates="0.0;-3.0;0.0">
							<rv:pid>
								<rv:p>1.000000e+00</rv:p>
								<rv:i>0.000000e+00</rv:i>
								<rv:d>0.000000e+00</rv:d>
								<rv:i_max>0.000000e+00</rv:i_max>
								<rv:i_min>0.000000e+00</rv:i_min>
							</rv:pid>
						</rv:servomotor>
						<rv:servomotor type="position" id="5__rotate" part_id="5" part_name="component_LFFF_ActiveHinge__joint" joint="component_LFFF_ActiveHinge__joint" coordinates="0.0;-4.0;0.0">
							<rv:pid>
								<rv:p>1.000000e+00</rv:p>
								<rv:i>0.000000e+00</rv:i>
								<rv:d>0.000000e+00</rv:d>
								<rv:i_max>0.000000e+00</rv:i_max>
								<rv:i_min>0.000000e+00</rv:i_min>
							</rv:pid>
						</rv:servomotor>
						<rv:servomotor type="position" id="9__rotate" part_id="9" part_name="component_LFFFFLF_ActiveHinge__joint" joint="component_LFFFFLF_ActiveHinge__joint" coordinates="-2.0;-5.0;0.0">
							<rv:pid>
								<rv:p>1.000000e+00</rv:p>
								<rv:i>0.000000e+00</rv:i>
								<rv:d>0.000000e+00</rv:d>
								<rv:i_max>0.000000e+00</rv:i_max>
								<rv:i_min>0.000000e+00</rv:i_min>
							</rv:pid>
						</rv:servomotor>
						<rv:servomotor type="position" id="11__rotate" part_id="11" part_name="component_LFFFFLRF_ActiveHinge__joint" joint="component_LFFFFLRF_ActiveHinge__joint" coordinates="-1.0;-7.0;0.0">
							<rv:pid>
								<rv:p>1.000000e+00</rv:p>
								<rv:i>0.000000e+00</rv:i>
								<rv:d>0.000000e+00</rv:d>
								<rv:i_max>0.000000e+00</rv:i_max>
								<rv:i_min>0.000000e+00</rv:i_min>
							</rv:pid>
						</rv:servomotor>
						<rv:servomotor type="position" id="14__rotate" part_id="14" part_name="component_LFFFFLRFFF_ActiveHinge__joint" joint="component_LFFFFLRFFF_ActiveHinge__joint" coordinates="-1.0;-9.0;0.0">
							<rv:pid>
								<rv:p>1.000000e+00</rv:p>
								<rv:i>0.000000e+00</rv:i>
								<rv:d>0.000000e+00</rv:d>
								<rv:i_max>0.000000e+00</rv:i_max>
								<rv:i_min>0.000000e+00</rv:i_min>
							</rv:pid>
						</rv:servomotor>
						<rv:servomotor type="position" id="15__rotate" part_id="15" part_name="component_LFFFFLRFFRR_ActiveHinge__joint" joint="component_LFFFFLRFFRR_ActiveHinge__joint" coordinates="0.0;-7.0;0.0">
							<rv:pid>
								<rv:p>1.000000e+00</rv:p>
								<rv:i>0.000000e+00</rv:i>
								<rv:d>0.000000e+00</rv:d>
								<rv:i_max>0.000000e+00</rv:i_max>
								<rv:i_min>0.000000e+00</rv:i_min>
							</rv:pid>
						</rv:servomotor>
					</rv:actuators>
				</rv:brain>
			</rv:robot_config>
		</plugin>
	</gazebo>
</robot>
