<?xml version="1.0" ?>
<robot name="turtle">
	<origin xyz="0.000000e+00 0.000000e+00 2.500000e-01" rpy="0.000000e+00 -0.000000e+00 0.000000e+00"/>
	<joint name="component_RR_ActiveHinge__joint" type="revolute">
		<origin xyz="7.594313e-02 -6.494313e-02 0.000000e+00" rpy="0.000000e+00 0.000000e+00 -1.570796e+00"/>
		<parent link="Core"/>
		<child link="RR_Leg"/>
		<axis xyz="0.000000e+00 1.000000e+00 0.000000e+00"/>
		<use_parent_model_frame>0</use_parent_model_frame>
		<limit lower="-1.5707963267948966" upper="1.5707963267948966" effort="0.9212" velocity="5.235988"/>
	</joint>
	<joint name="component_RL_ActiveHinge__joint" type="revolute">
		<origin xyz="7.594313e-02 6.494313e-02 -1.859624e-18" rpy="1.570796e+00 5.551115e-17 1.570796e+00"/>
		<parent link="Core"/>
		<child link="RL_Leg"/>
		<axis xyz="0.000000e+00 1.000000e+00 0.000000e+00"/>
		<use_parent_model_frame>0</use_parent_model_frame>
		<limit lower="-1.5707963267948966" upper="1.5707963267948966" effort="0.9212" velocity="5.235988"/>
	</joint>
	<joint name="component_RLF_ActiveHinge__joint" type="revolute">
		<origin xyz="7.280000e-02 0.000000e+00 0.000000e+00" rpy="-1.570796e+00 0.000000e+00 0.000000e+00"/>
		<parent link="RL_Leg"/>
		<child link="RLF_Leg"/>
		<axis xyz="0.000000e+00 1.000000e+00 0.000000e+00"/>
		<use_parent_model_frame>0</use_parent_model_frame>
		<limit lower="-1.5707963267948966" upper="1.5707963267948966" effort="0.9212" velocity="5.235988"/>
	</joint>
	<joint name="component_RLFFR_ActiveHinge__joint" type="revolute">
		<origin xyz="7.074313e-02 -6.494313e-02 0.000000e+00" rpy="0.000000e+00 0.000000e+00 -1.570796e+00"/>
		<parent link="RLF_Leg"/>
		<child link="RLFFR_Leg"/>
		<axis xyz="0.000000e+00 1.000000e+00 0.000000e+00"/>
		<use_parent_model_frame>0</use_parent_model_frame>
		<limit lower="-1.5707963267948966" upper="1.5707963267948966" effort="0.9212" velocity="5.235988"/>
	</joint>
	<joint name="component_RLFFRFR_ActiveHinge__joint" type="revolute">
		<origin xyz="7.074313e-02 -6.494313e-02 0.000000e+00" rpy="0.000000e+00 0.000000e+00 -1.570796e+00"/>
		<parent link="RLFFR_Leg"/>
		<child link="RLFFRFR_Leg"/>
		<axis xyz="0.000000e+00 1.000000e+00 0.000000e+00"/>
		<use_parent_model_frame>0</use_parent_model_frame>
		<limit lower="-1.5707963267948966" upper="1.5707963267948966" effort="0.9212" velocity="5.235988"/>
	</joint>
	<joint name="component_RLFFRFRFR_ActiveHinge__joint" type="revolute">
		<origin xyz="7.074313e-02 -6.494313e-02 0.000000e+00" rpy="0.000000e+00 0.000000e+00 -1.570796e+00"/>
		<parent link="RLFFRFR_Leg"/>
		<child link="RLFFRFRFR_Leg"/>
		<axis xyz="0.000000e+00 1.000000e+00 0.000000e+00"/>
		<use_parent_model_frame>0</use_parent_model_frame>
		<limit lower="-1.5707963267948966" upper="1.5707963267948966" effort="0.9212" velocity="5.235988"/>
	</joint>
	<joint name="component_RLFFRFRFL_ActiveHinge__joint" type="revolute">
		<origin xyz="7.074313e-02 6.494313e-02 -1.859624e-18" rpy="1.570796e+00 5.551115e-17 1.570796e+00"/>
		<parent link="RLFFRFR_Leg"/>
		<child link="RLFFRFRFL_Leg"/>
		<axis xyz="0.000000e+00 1.000000e+00 0.000000e+00"/>
		<use_parent_model_frame>0</use_parent_model_frame>
		<limit lower="-1.5707963267948966" upper="1.5707963267948966" effort="0.9212" velocity="5.235988"/>
	</joint>
	<joint name="component_RLFFRFRFLF_ActiveHinge__joint" type="revolute">
		<origin xyz="7.280000e-02 0.000000e+00 0.000000e+00" rpy="-1.570796e+00 0.000000e+00 0.000000e+00"/>
		<parent link="RLFFRFRFL_Leg"/>
		<child link="RLFFRFRFLF_Leg"/>
		<axis xyz="0.000000e+00 1.000000e+00 0.000000e+00"/>
		<use_parent_model_frame>0</use_parent_model_frame>
		<limit lower="-1.5707963267948966" upper="1.5707963267948966" effort="0.9212" velocity="5.235988"/>
	</joint>
	<joint name="component_RLFFRFRFLFF_ActiveHinge__joint" type="revolute">
		<origin xyz="7.280000e-02 0.000000e+00 0.000000e+00" rpy="0.000000e+00 -0.000000e+00 0.000000e+00"/>
		<parent link="RLFFRFRFLF_Leg"/>
		<child link="RLFFRFRFLFF_Leg"/>
		<axis xyz="0.000000e+00 1.000000e+00 0.000000e+00"/>
		<use_parent_model_frame>0</use_parent_model_frame>
		<limit lower="-1.5707963267948966" upper="1.5707963267948966" effort="0.9212" velocity="5.235988"/>
	</joint>
	<joint name="component_RLFFRFRFLFFF_ActiveHinge__joint" type="revolute">
		<origin xyz="7.280000e-02 0.000000e+00 0.000000e+00" rpy="0.000000e+00 -0.000000e+00 0.000000e+00"/>
		<parent link="RLFFRFRFLFF_Leg"/>
		<child link="RLFFRFRFLFFF_Leg"/>
		<axis xyz="0.000000e+00 1.000000e+00 0.000000e+00"/>
		<use_parent_model_frame>0</use_parent_model_frame>
		<limit lower="-1.5707963267948966" upper="1.5707963267948966" effort="0.9212" velocity="5.235988"/>
	</joint>
	<joint name="component_RLFFRFL_ActiveHinge__joint" type="revolute">
		<origin xyz="7.074313e-02 6.494313e-02 -1.859624e-18" rpy="1.570796e+00 5.551115e-17 1.570796e+00"/>
		<parent link="RLFFR_Leg"/>
		<child link="RLFFRFL_Leg"/>
		<axis xyz="0.000000e+00 1.000000e+00 0.000000e+00"/>
		<use_parent_model_frame>0</use_parent_model_frame>
		<limit lower="-1.5707963267948966" upper="1.5707963267948966" effort="0.9212" velocity="5.235988"/>
	</joint>
	<joint name="component_RLFFRFLF_ActiveHinge__joint" type="revolute">
		<origin xyz="7.280000e-02 0.000000e+00 0.000000e+00" rpy="-1.570796e+00 0.000000e+00 0.000000e+00"/>
		<parent link="RLFFRFL_Leg"/>
		<child link="RLFFRFLF_Leg"/>
		<axis xyz="0.000000e+00 1.000000e+00 0.000000e+00"/>
		<use_parent_model_frame>0</use_parent_model_frame>
		<limit lower="-1.5707963267948966" upper="1.5707963267948966" effort="0.9212" velocity="5.235988"/>
	</joint>
	<joint name="component_RLFFL_ActiveHinge__joint" type="revolute">
		<origin xyz="7.074313e-02 6.494313e-02 -1.859624e-18" rpy="1.570796e+00 5.551115e-17 1.570796e+00"/>
		<parent link="RLF_Leg"/>
		<child link="RLFFL_Leg"/>
		<axis xyz="0.000000e+00 1.000000e+00 0.000000e+00"/>
		<use_parent_model_frame>0</use_parent_model_frame>
		<limit lower="-1.5707963267948966" upper="1.5707963267948966" effort="0.9212" velocity="5.235988"/>
	</joint>
	<link name="Core">
		<origin xyz="1.307630e-02 -3.590073e-19 -4.574615e-20" rpy="0.000000e+00 -0.000000e+00 0.000000e+00"/>
		<sensor name="core-imu_sensor" type="imu">
			<origin xyz="0.000000e+00 0.000000e+00 0.000000e+00" rpy="0.000000e+00 -0.000000e+00 0.000000e+00"/>
			<always_on>True</always_on>
		</sensor>
		<visual name="component__CoreComponent__box_visual">
			<origin xyz="0.000000e+00 0.000000e+00 0.000000e+00" rpy="0.000000e+00 -0.000000e+00 0.000000e+00"/>
			<material name="no_texture">
				<color rgba="1 1 0 1.0"/>
			</material>
			<geometry>
				<mesh filename="package://models/rg_robot/meshes/CoreComponent.dae"/>
			</geometry>
		</visual>
		<collision name="component__CoreComponent__box_collision">
			<origin xyz="0.000000e+00 0.000000e+00 0.000000e+00" rpy="0.000000e+00 -0.000000e+00 0.000000e+00"/>
			<contact>
				<lateral_friction value="0.8"/>
				<rolling_friction value="0"/>
				<spinning_friction value="1"/>
				<stiffness value="90000"/>
				<damping value="3333333.3333333335"/>
			</contact>
			<gazebo name="component__CoreComponent__box">
				<mu1 value="1.0"/>
				<mu2 value="1.0"/>
				<slip1 value="0.01"/>
				<slip2 value="0.01"/>
			</gazebo>
			<geometry>
				<box size="8.900000e-02 8.900000e-02 6.030000e-02"/>
			</geometry>
		</collision>
		<visual name="component_R_FixedBrick__box_visual">
			<origin xyz="7.594313e-02 0.000000e+00 0.000000e+00" rpy="0.000000e+00 0.000000e+00 -1.570796e+00"/>
			<material name="no_texture">
				<color rgba="0 0 1 1.0"/>
			</material>
			<geometry>
				<mesh filename="package://models/rg_robot/meshes/FixedBrick.dae"/>
			</geometry>
		</visual>
		<collision name="component_R_FixedBrick__box_collision">
			<origin xyz="7.594313e-02 0.000000e+00 0.000000e+00" rpy="0.000000e+00 0.000000e+00 -1.570796e+00"/>
			<contact>
				<lateral_friction value="0.8"/>
				<rolling_friction value="0"/>
				<spinning_friction value="1"/>
				<stiffness value="90000"/>
				<damping value="3333333.3333333335"/>
			</contact>
			<gazebo name="component_R_FixedBrick__box">
				<mu1 value="1.0"/>
				<mu2 value="1.0"/>
				<slip1 value="0.01"/>
				<slip2 value="0.01"/>
			</gazebo>
			<geometry>
				<box size="6.288625e-02 6.288625e-02 6.030000e-02"/>
			</geometry>
		</collision>
		<visual name="component_RR_ActiveHinge__frame_visual">
			<origin xyz="7.594313e-02 -5.406813e-02 0.000000e+00" rpy="0.000000e+00 0.000000e+00 -1.570796e+00"/>
			<material name="no_texture">
				<color rgba="1 0.08 0.58 1.0"/>
			</material>
			<geometry>
				<mesh filename="package://models/rg_robot/meshes/ActiveHinge_Frame.dae"/>
			</geometry>
		</visual>
		<collision name="component_RR_ActiveHinge__frame_collision">
			<origin xyz="7.594313e-02 -5.406813e-02 0.000000e+00" rpy="0.000000e+00 0.000000e+00 -1.570796e+00"/>
			<contact>
				<lateral_friction value="0.8"/>
				<rolling_friction value="0"/>
				<spinning_friction value="1"/>
				<stiffness value="90000"/>
				<damping value="3333333.3333333335"/>
			</contact>
			<gazebo name="component_RR_ActiveHinge__frame">
				<mu1 value="1.0"/>
				<mu2 value="1.0"/>
				<slip1 value="0.01"/>
				<slip2 value="0.01"/>
			</gazebo>
			<geometry>
				<box size="4.525000e-02 5.300000e-02 1.658910e-02"/>
			</geometry>
		</collision>
		<visual name="component_RL_ActiveHinge__frame_visual">
			<origin xyz="7.594313e-02 5.406812e-02 -1.255940e-18" rpy="1.570796e+00 5.551115e-17 1.570796e+00"/>
			<material name="no_texture">
				<color rgba="0.7 0 0 1.0"/>
			</material>
			<geometry>
				<mesh filename="package://models/rg_robot/meshes/ActiveHinge_Frame.dae"/>
			</geometry>
		</visual>
		<collision name="component_RL_ActiveHinge__frame_collision">
			<origin xyz="7.594313e-02 5.406812e-02 -1.255940e-18" rpy="1.570796e+00 5.551115e-17 1.570796e+00"/>
			<contact>
				<lateral_friction value="0.8"/>
				<rolling_friction value="0"/>
				<spinning_friction value="1"/>
				<stiffness value="90000"/>
				<damping value="3333333.3333333335"/>
			</contact>
			<gazebo name="component_RL_ActiveHinge__frame">
				<mu1 value="1.0"/>
				<mu2 value="1.0"/>
				<slip1 value="0.01"/>
				<slip2 value="0.01"/>
			</gazebo>
			<geometry>
				<box size="4.525000e-02 5.300000e-02 1.658910e-02"/>
			</geometry>
		</collision>
		<inertial>
			<origin xyz="1.307630e-02 -3.590073e-19 -4.574615e-20" rpy="0.000000e+00 -0.000000e+00 0.000000e+00"/>
			<mass value="0.30200000000000005"/>
			<inertia ixx="0.0003306446478355758" ixy="6.776263578034403e-21" ixz="2.2330957949664867e-21" iyy="0.0005136677629415003" iyz="1.299194471666755e-21" izz="0.0006689738473392579"/>
		</inertial>
	</link>
	<link name="RR_Leg">
		<origin xyz="1.015000e-02 0.000000e+00 0.000000e+00" rpy="0.000000e+00 -0.000000e+00 0.000000e+00"/>
		<visual name="component_RR_ActiveHinge__servo_visual">
			<origin xyz="2.990000e-02 0.000000e+00 0.000000e+00" rpy="0.000000e+00 -0.000000e+00 0.000000e+00"/>
			<material name="no_texture">
				<color rgba="1 0.08 0.58 1.0"/>
			</material>
			<geometry>
				<mesh filename="package://models/rg_robot/meshes/ActiveCardanHinge_Servo_Holder.dae"/>
			</geometry>
		</visual>
		<collision name="component_RR_ActiveHinge__servo_collision">
			<origin xyz="1.015000e-02 0.000000e+00 0.000000e+00" rpy="0.000000e+00 -0.000000e+00 0.000000e+00"/>
			<contact>
				<lateral_friction value="0.8"/>
				<rolling_friction value="0"/>
				<spinning_friction value="1"/>
				<stiffness value="90000"/>
				<damping value="3333333.3333333335"/>
			</contact>
			<gazebo name="component_RR_ActiveHinge__servo">
				<mu1 value="1.0"/>
				<mu2 value="1.0"/>
				<slip1 value="0.01"/>
				<slip2 value="0.01"/>
			</gazebo>
			<geometry>
				<box size="5.830000e-02 5.120000e-02 2.000000e-02"/>
			</geometry>
		</collision>
		<collision name="component_RR_ActiveHinge__servo2_collision">
			<origin xyz="3.830000e-02 0.000000e+00 0.000000e+00" rpy="0.000000e+00 -0.000000e+00 0.000000e+00"/>
			<contact>
				<lateral_friction value="0.8"/>
				<rolling_friction value="0"/>
				<spinning_friction value="1"/>
				<stiffness value="90000"/>
				<damping value="3333333.3333333335"/>
			</contact>
			<gazebo name="component_RR_ActiveHinge__servo2">
				<mu1 value="1.0"/>
				<mu2 value="1.0"/>
				<slip1 value="0.01"/>
				<slip2 value="0.01"/>
			</gazebo>
			<geometry>
				<box size="2.000000e-03 5.300000e-02 5.300000e-02"/>
			</geometry>
		</collision>
		<inertial>
			<origin xyz="1.015000e-02 0.000000e+00 0.000000e+00" rpy="0.000000e+00 -0.000000e+00 0.000000e+00"/>
			<mass value="0.058"/>
			<inertia ixx="1.460362666666667e-05" ixy="0.0" ixz="0.0" iyy="1.836130166666667e-05" iyz="0.0" izz="2.909826166666667e-05"/>
		</inertial>
	</link>
	<link name="RL_Leg">
		<origin xyz="1.840399e-02 0.000000e+00 0.000000e+00" rpy="0.000000e+00 -0.000000e+00 0.000000e+00"/>
		<visual name="component_RL_ActiveHinge__servo_visual">
			<origin xyz="2.990000e-02 0.000000e+00 0.000000e+00" rpy="0.000000e+00 -0.000000e+00 0.000000e+00"/>
			<material name="no_texture">
				<color rgba="0.7 0 0 1.0"/>
			</material>
			<geometry>
				<mesh filename="package://models/rg_robot/meshes/ActiveCardanHinge_Servo_Holder.dae"/>
			</geometry>
		</visual>
		<collision name="component_RL_ActiveHinge__servo_collision">
			<origin xyz="1.015000e-02 0.000000e+00 0.000000e+00" rpy="0.000000e+00 -0.000000e+00 0.000000e+00"/>
			<contact>
				<lateral_friction value="0.8"/>
				<rolling_friction value="0"/>
				<spinning_friction value="1"/>
				<stiffness value="90000"/>
				<damping value="3333333.3333333335"/>
			</contact>
			<gazebo name="component_RL_ActiveHinge__servo">
				<mu1 value="1.0"/>
				<mu2 value="1.0"/>
				<slip1 value="0.01"/>
				<slip2 value="0.01"/>
			</gazebo>
			<geometry>
				<box size="5.830000e-02 5.120000e-02 2.000000e-02"/>
			</geometry>
		</collision>
		<collision name="component_RL_ActiveHinge__servo2_collision">
			<origin xyz="3.830000e-02 0.000000e+00 0.000000e+00" rpy="0.000000e+00 -0.000000e+00 0.000000e+00"/>
			<contact>
				<lateral_friction value="0.8"/>
				<rolling_friction value="0"/>
				<spinning_friction value="1"/>
				<stiffness value="90000"/>
				<damping value="3333333.3333333335"/>
			</contact>
			<gazebo name="component_RL_ActiveHinge__servo2">
				<mu1 value="1.0"/>
				<mu2 value="1.0"/>
				<slip1 value="0.01"/>
				<slip2 value="0.01"/>
			</gazebo>
			<geometry>
				<box size="2.000000e-03 5.300000e-02 5.300000e-02"/>
			</geometry>
		</collision>
		<visual name="component_RLF_ActiveHinge__frame_visual">
			<origin xyz="6.192500e-02 0.000000e+00 0.000000e+00" rpy="-1.570796e+00 0.000000e+00 0.000000e+00"/>
			<material name="no_texture">
				<color rgba="1 0.08 0.58 1.0"/>
			</material>
			<geometry>
				<mesh filename="package://models/rg_robot/meshes/ActiveHinge_Frame.dae"/>
			</geometry>
		</visual>
		<collision name="component_RLF_ActiveHinge__frame_collision">
			<origin xyz="6.192500e-02 0.000000e+00 0.000000e+00" rpy="-1.570796e+00 0.000000e+00 0.000000e+00"/>
			<contact>
				<lateral_friction value="0.8"/>
				<rolling_friction value="0"/>
				<spinning_friction value="1"/>
				<stiffness value="90000"/>
				<damping value="3333333.3333333335"/>
			</contact>
			<gazebo name="component_RLF_ActiveHinge__frame">
				<mu1 value="1.0"/>
				<mu2 value="1.0"/>
				<slip1 value="0.01"/>
				<slip2 value="0.01"/>
			</gazebo>
			<geometry>
				<box size="4.525000e-02 5.300000e-02 1.658910e-02"/>
			</geometry>
		</collision>
		<inertial>
			<origin xyz="1.840399e-02 0.000000e+00 0.000000e+00" rpy="0.000000e+00 -0.000000e+00 0.000000e+00"/>
			<mass value="0.069"/>
			<inertia ixx="1.7430808385575836e-05" ixy="0.0" ixz="0.0" iyy="4.759945640398551e-05" iyz="0.0" izz="5.601376478956134e-05"/>
		</inertial>
	</link>
	<link name="RLF_Leg">
		<origin xyz="5.911588e-02 -7.744301e-19 -9.868098e-20" rpy="0.000000e+00 -0.000000e+00 0.000000e+00"/>
		<visual name="component_RLF_ActiveHinge__servo_visual">
			<origin xyz="2.990000e-02 0.000000e+00 0.000000e+00" rpy="0.000000e+00 -0.000000e+00 0.000000e+00"/>
			<material name="no_texture">
				<color rgba="1 0.08 0.58 1.0"/>
			</material>
			<geometry>
				<mesh filename="package://models/rg_robot/meshes/ActiveCardanHinge_Servo_Holder.dae"/>
			</geometry>
		</visual>
		<collision name="component_RLF_ActiveHinge__servo_collision">
			<origin xyz="1.015000e-02 0.000000e+00 0.000000e+00" rpy="0.000000e+00 -0.000000e+00 0.000000e+00"/>
			<contact>
				<lateral_friction value="0.8"/>
				<rolling_friction value="0"/>
				<spinning_friction value="1"/>
				<stiffness value="90000"/>
				<damping value="3333333.3333333335"/>
			</contact>
			<gazebo name="component_RLF_ActiveHinge__servo">
				<mu1 value="1.0"/>
				<mu2 value="1.0"/>
				<slip1 value="0.01"/>
				<slip2 value="0.01"/>
			</gazebo>
			<geometry>
				<box size="5.830000e-02 5.120000e-02 2.000000e-02"/>
			</geometry>
		</collision>
		<collision name="component_RLF_ActiveHinge__servo2_collision">
			<origin xyz="3.830000e-02 0.000000e+00 0.000000e+00" rpy="0.000000e+00 -0.000000e+00 0.000000e+00"/>
			<contact>
				<lateral_friction value="0.8"/>
				<rolling_friction value="0"/>
				<spinning_friction value="1"/>
				<stiffness value="90000"/>
				<damping value="3333333.3333333335"/>
			</contact>
			<gazebo name="component_RLF_ActiveHinge__servo2">
				<mu1 value="1.0"/>
				<mu2 value="1.0"/>
				<slip1 value="0.01"/>
				<slip2 value="0.01"/>
			</gazebo>
			<geometry>
				<box size="2.000000e-03 5.300000e-02 5.300000e-02"/>
			</geometry>
		</collision>
		<visual name="component_RLFF_FixedBrick__box_visual">
			<origin xyz="7.074313e-02 0.000000e+00 0.000000e+00" rpy="0.000000e+00 0.000000e+00 -1.570796e+00"/>
			<material name="no_texture">
				<color rgba="0 0 1 1.0"/>
			</material>
			<geometry>
				<mesh filename="package://models/rg_robot/meshes/FixedBrick.dae"/>
			</geometry>
		</visual>
		<collision name="component_RLFF_FixedBrick__box_collision">
			<origin xyz="7.074313e-02 0.000000e+00 0.000000e+00" rpy="0.000000e+00 0.000000e+00 -1.570796e+00"/>
			<contact>
				<lateral_friction value="0.8"/>
				<rolling_friction value="0"/>
				<spinning_friction value="1"/>
				<stiffness value="90000"/>
				<damping value="3333333.3333333335"/>
			</contact>
			<gazebo name="component_RLFF_FixedBrick__box">
				<mu1 value="1.0"/>
				<mu2 value="1.0"/>
				<slip1 value="0.01"/>
				<slip2 value="0.01"/>
			</gazebo>
			<geometry>
				<box size="6.288625e-02 6.288625e-02 6.030000e-02"/>
			</geometry>
		</collision>
		<visual name="component_RLFFF_FixedBrick__box_visual">
			<origin xyz="1.336294e-01 0.000000e+00 0.000000e+00" rpy="0.000000e+00 0.000000e+00 -1.570796e+00"/>
			<material name="no_texture">
				<color rgba="0 0 1 1.0"/>
			</material>
			<geometry>
				<mesh filename="package://models/rg_robot/meshes/FixedBrick.dae"/>
			</geometry>
		</visual>
		<collision name="component_RLFFF_FixedBrick__box_collision">
			<origin xyz="1.336294e-01 0.000000e+00 0.000000e+00" rpy="0.000000e+00 0.000000e+00 -1.570796e+00"/>
			<contact>
				<lateral_friction value="0.8"/>
				<rolling_friction value="0"/>
				<spinning_friction value="1"/>
				<stiffness value="90000"/>
				<damping value="3333333.3333333335"/>
			</contact>
			<gazebo name="component_RLFFF_FixedBrick__box">
				<mu1 value="1.0"/>
				<mu2 value="1.0"/>
				<slip1 value="0.01"/>
				<slip2 value="0.01"/>
			</gazebo>
			<geometry>
				<box size="6.288625e-02 6.288625e-02 6.030000e-02"/>
			</geometry>
		</collision>
		<visual name="component_RLFFR_ActiveHinge__frame_visual">
			<origin xyz="7.074313e-02 -5.406813e-02 0.000000e+00" rpy="0.000000e+00 0.000000e+00 -1.570796e+00"/>
			<material name="no_texture">
				<color rgba="1 0.08 0.58 1.0"/>
			</material>
			<geometry>
				<mesh filename="package://models/rg_robot/meshes/ActiveHinge_Frame.dae"/>
			</geometry>
		</visual>
		<collision name="component_RLFFR_ActiveHinge__frame_collision">
			<origin xyz="7.074313e-02 -5.406813e-02 0.000000e+00" rpy="0.000000e+00 0.000000e+00 -1.570796e+00"/>
			<contact>
				<lateral_friction value="0.8"/>
				<rolling_friction value="0"/>
				<spinning_friction value="1"/>
				<stiffness value="90000"/>
				<damping value="3333333.3333333335"/>
			</contact>
			<gazebo name="component_RLFFR_ActiveHinge__frame">
				<mu1 value="1.0"/>
				<mu2 value="1.0"/>
				<slip1 value="0.01"/>
				<slip2 value="0.01"/>
			</gazebo>
			<geometry>
				<box size="4.525000e-02 5.300000e-02 1.658910e-02"/>
			</geometry>
		</collision>
		<visual name="component_RLFFL_ActiveHinge__frame_visual">
			<origin xyz="7.074313e-02 5.406812e-02 -1.255940e-18" rpy="1.570796e+00 5.551115e-17 1.570796e+00"/>
			<material name="no_texture">
				<color rgba="0.7 0 0 1.0"/>
			</material>
			<geometry>
				<mesh filename="package://models/rg_robot/meshes/ActiveHinge_Frame.dae"/>
			</geometry>
		</visual>
		<collision name="component_RLFFL_ActiveHinge__frame_collision">
			<origin xyz="7.074313e-02 5.406812e-02 -1.255940e-18" rpy="1.570796e+00 5.551115e-17 1.570796e+00"/>
			<contact>
				<lateral_friction value="0.8"/>
				<rolling_friction value="0"/>
				<spinning_friction value="1"/>
				<stiffness value="90000"/>
				<damping value="3333333.3333333335"/>
			</contact>
			<gazebo name="component_RLFFL_ActiveHinge__frame">
				<mu1 value="1.0"/>
				<mu2 value="1.0"/>
				<slip1 value="0.01"/>
				<slip2 value="0.01"/>
			</gazebo>
			<geometry>
				<box size="4.525000e-02 5.300000e-02 1.658910e-02"/>
			</geometry>
		</collision>
		<inertial>
			<origin xyz="5.911588e-02 -7.744301e-19 -9.868098e-20" rpy="0.000000e+00 -0.000000e+00 0.000000e+00"/>
			<mass value="0.14"/>
			<inertia ixx="0.0001234524922665654" ixy="2.541098841762901e-21" ixz="1.525203631599504e-21" iyy="0.0003746315018224425" iyz="1.2991944716667552e-21" izz="0.0004522020639845229"/>
		</inertial>
	</link>
	<link name="RLFFR_Leg">
		<origin xyz="5.911588e-02 -7.744301e-19 -9.868098e-20" rpy="0.000000e+00 -0.000000e+00 0.000000e+00"/>
		<visual name="component_RLFFR_ActiveHinge__servo_visual">
			<origin xyz="2.990000e-02 0.000000e+00 0.000000e+00" rpy="0.000000e+00 -0.000000e+00 0.000000e+00"/>
			<material name="no_texture">
				<color rgba="1 0.08 0.58 1.0"/>
			</material>
			<geometry>
				<mesh filename="package://models/rg_robot/meshes/ActiveCardanHinge_Servo_Holder.dae"/>
			</geometry>
		</visual>
		<collision name="component_RLFFR_ActiveHinge__servo_collision">
			<origin xyz="1.015000e-02 0.000000e+00 0.000000e+00" rpy="0.000000e+00 -0.000000e+00 0.000000e+00"/>
			<contact>
				<lateral_friction value="0.8"/>
				<rolling_friction value="0"/>
				<spinning_friction value="1"/>
				<stiffness value="90000"/>
				<damping value="3333333.3333333335"/>
			</contact>
			<gazebo name="component_RLFFR_ActiveHinge__servo">
				<mu1 value="1.0"/>
				<mu2 value="1.0"/>
				<slip1 value="0.01"/>
				<slip2 value="0.01"/>
			</gazebo>
			<geometry>
				<box size="5.830000e-02 5.120000e-02 2.000000e-02"/>
			</geometry>
		</collision>
		<collision name="component_RLFFR_ActiveHinge__servo2_collision">
			<origin xyz="3.830000e-02 0.000000e+00 0.000000e+00" rpy="0.000000e+00 -0.000000e+00 0.000000e+00"/>
			<contact>
				<lateral_friction value="0.8"/>
				<rolling_friction value="0"/>
				<spinning_friction value="1"/>
				<stiffness value="90000"/>
				<damping value="3333333.3333333335"/>
			</contact>
			<gazebo name="component_RLFFR_ActiveHinge__servo2">
				<mu1 value="1.0"/>
				<mu2 value="1.0"/>
				<slip1 value="0.01"/>
				<slip2 value="0.01"/>
			</gazebo>
			<geometry>
				<box size="2.000000e-03 5.300000e-02 5.300000e-02"/>
			</geometry>
		</collision>
		<visual name="component_RLFFRF_FixedBrick__box_visual">
			<origin xyz="7.074313e-02 0.000000e+00 0.000000e+00" rpy="0.000000e+00 0.000000e+00 -1.570796e+00"/>
			<material name="no_texture">
				<color rgba="0 0 1 1.0"/>
			</material>
			<geometry>
				<mesh filename="package://models/rg_robot/meshes/FixedBrick.dae"/>
			</geometry>
		</visual>
		<collision name="component_RLFFRF_FixedBrick__box_collision">
			<origin xyz="7.074313e-02 0.000000e+00 0.000000e+00" rpy="0.000000e+00 0.000000e+00 -1.570796e+00"/>
			<contact>
				<lateral_friction value="0.8"/>
				<rolling_friction value="0"/>
				<spinning_friction value="1"/>
				<stiffness value="90000"/>
				<damping value="3333333.3333333335"/>
			</contact>
			<gazebo name="component_RLFFRF_FixedBrick__box">
				<mu1 value="1.0"/>
				<mu2 value="1.0"/>
				<slip1 value="0.01"/>
				<slip2 value="0.01"/>
			</gazebo>
			<geometry>
				<box size="6.288625e-02 6.288625e-02 6.030000e-02"/>
			</geometry>
		</collision>
		<visual name="component_RLFFRFF_FixedBrick__box_visual">
			<origin xyz="1.336294e-01 0.000000e+00 0.000000e+00" rpy="0.000000e+00 0.000000e+00 -1.570796e+00"/>
			<material name="no_texture">
				<color rgba="0 0 1 1.0"/>
			</material>
			<geometry>
				<mesh filename="package://models/rg_robot/meshes/FixedBrick.dae"/>
			</geometry>
		</visual>
		<collision name="component_RLFFRFF_FixedBrick__box_collision">
			<origin xyz="1.336294e-01 0.000000e+00 0.000000e+00" rpy="0.000000e+00 0.000000e+00 -1.570796e+00"/>
			<contact>
				<lateral_friction value="0.8"/>
				<rolling_friction value="0"/>
				<spinning_friction value="1"/>
				<stiffness value="90000"/>
				<damping value="3333333.3333333335"/>
			</contact>
			<gazebo name="component_RLFFRFF_FixedBrick__box">
				<mu1 value="1.0"/>
				<mu2 value="1.0"/>
				<slip1 value="0.01"/>
				<slip2 value="0.01"/>
			</gazebo>
			<geometry>
				<box size="6.288625e-02 6.288625e-02 6.030000e-02"/>
			</geometry>
		</collision>
		<visual name="component_RLFFRFR_ActiveHinge__frame_visual">
			<origin xyz="7.074313e-02 -5.406813e-02 0.000000e+00" rpy="0.000000e+00 0.000000e+00 -1.570796e+00"/>
			<material name="no_texture">
				<color rgba="1 0.08 0.58 1.0"/>
			</material>
			<geometry>
				<mesh filename="package://models/rg_robot/meshes/ActiveHinge_Frame.dae"/>
			</geometry>
		</visual>
		<collision name="component_RLFFRFR_ActiveHinge__frame_collision">
			<origin xyz="7.074313e-02 -5.406813e-02 0.000000e+00" rpy="0.000000e+00 0.000000e+00 -1.570796e+00"/>
			<contact>
				<lateral_friction value="0.8"/>
				<rolling_friction value="0"/>
				<spinning_friction value="1"/>
				<stiffness value="90000"/>
				<damping value="3333333.3333333335"/>
			</contact>
			<gazebo name="component_RLFFRFR_ActiveHinge__frame">
				<mu1 value="1.0"/>
				<mu2 value="1.0"/>
				<slip1 value="0.01"/>
				<slip2 value="0.01"/>
			</gazebo>
			<geometry>
				<box size="4.525000e-02 5.300000e-02 1.658910e-02"/>
			</geometry>
		</collision>
		<visual name="component_RLFFRFL_ActiveHinge__frame_visual">
			<origin xyz="7.074313e-02 5.406812e-02 -1.255940e-18" rpy="1.570796e+00 5.551115e-17 1.570796e+00"/>
			<material name="no_texture">
				<color rgba="0.7 0 0 1.0"/>
			</material>
			<geometry>
				<mesh filename="package://models/rg_robot/meshes/ActiveHinge_Frame.dae"/>
			</geometry>
		</visual>
		<collision name="component_RLFFRFL_ActiveHinge__frame_collision">
			<origin xyz="7.074313e-02 5.406812e-02 -1.255940e-18" rpy="1.570796e+00 5.551115e-17 1.570796e+00"/>
			<contact>
				<lateral_friction value="0.8"/>
				<rolling_friction value="0"/>
				<spinning_friction value="1"/>
				<stiffness value="90000"/>
				<damping value="3333333.3333333335"/>
			</contact>
			<gazebo name="component_RLFFRFL_ActiveHinge__frame">
				<mu1 value="1.0"/>
				<mu2 value="1.0"/>
				<slip1 value="0.01"/>
				<slip2 value="0.01"/>
			</gazebo>
			<geometry>
				<box size="4.525000e-02 5.300000e-02 1.658910e-02"/>
			</geometry>
		</collision>
		<inertial>
			<origin xyz="5.911588e-02 -7.744301e-19 -9.868098e-20" rpy="0.000000e+00 -0.000000e+00 0.000000e+00"/>
			<mass value="0.14"/>
			<inertia ixx="0.0001234524922665654" ixy="2.541098841762901e-21" ixz="1.525203631599504e-21" iyy="0.0003746315018224425" iyz="1.2991944716667552e-21" izz="0.0004522020639845229"/>
		</inertial>
	</link>
	<link name="RLFFRFR_Leg">
		<origin xyz="3.879402e-02 -9.856383e-19 -1.255940e-19" rpy="0.000000e+00 -0.000000e+00 0.000000e+00"/>
		<visual name="component_RLFFRFR_ActiveHinge__servo_visual">
			<origin xyz="2.990000e-02 0.000000e+00 0.000000e+00" rpy="0.000000e+00 -0.000000e+00 0.000000e+00"/>
			<material name="no_texture">
				<color rgba="1 0.08 0.58 1.0"/>
			</material>
			<geometry>
				<mesh filename="package://models/rg_robot/meshes/ActiveCardanHinge_Servo_Holder.dae"/>
			</geometry>
		</visual>
		<collision name="component_RLFFRFR_ActiveHinge__servo_collision">
			<origin xyz="1.015000e-02 0.000000e+00 0.000000e+00" rpy="0.000000e+00 -0.000000e+00 0.000000e+00"/>
			<contact>
				<lateral_friction value="0.8"/>
				<rolling_friction value="0"/>
				<spinning_friction value="1"/>
				<stiffness value="90000"/>
				<damping value="3333333.3333333335"/>
			</contact>
			<gazebo name="component_RLFFRFR_ActiveHinge__servo">
				<mu1 value="1.0"/>
				<mu2 value="1.0"/>
				<slip1 value="0.01"/>
				<slip2 value="0.01"/>
			</gazebo>
			<geometry>
				<box size="5.830000e-02 5.120000e-02 2.000000e-02"/>
			</geometry>
		</collision>
		<collision name="component_RLFFRFR_ActiveHinge__servo2_collision">
			<origin xyz="3.830000e-02 0.000000e+00 0.000000e+00" rpy="0.000000e+00 -0.000000e+00 0.000000e+00"/>
			<contact>
				<lateral_friction value="0.8"/>
				<rolling_friction value="0"/>
				<spinning_friction value="1"/>
				<stiffness value="90000"/>
				<damping value="3333333.3333333335"/>
			</contact>
			<gazebo name="component_RLFFRFR_ActiveHinge__servo2">
				<mu1 value="1.0"/>
				<mu2 value="1.0"/>
				<slip1 value="0.01"/>
				<slip2 value="0.01"/>
			</gazebo>
			<geometry>
				<box size="2.000000e-03 5.300000e-02 5.300000e-02"/>
			</geometry>
		</collision>
		<visual name="component_RLFFRFRF_FixedBrick__box_visual">
			<origin xyz="7.074313e-02 0.000000e+00 0.000000e+00" rpy="0.000000e+00 0.000000e+00 -1.570796e+00"/>
			<material name="no_texture">
				<color rgba="0 0 1 1.0"/>
			</material>
			<geometry>
				<mesh filename="package://models/rg_robot/meshes/FixedBrick.dae"/>
			</geometry>
		</visual>
		<collision name="component_RLFFRFRF_FixedBrick__box_collision">
			<origin xyz="7.074313e-02 0.000000e+00 0.000000e+00" rpy="0.000000e+00 0.000000e+00 -1.570796e+00"/>
			<contact>
				<lateral_friction value="0.8"/>
				<rolling_friction value="0"/>
				<spinning_friction value="1"/>
				<stiffness value="90000"/>
				<damping value="3333333.3333333335"/>
			</contact>
			<gazebo name="component_RLFFRFRF_FixedBrick__box">
				<mu1 value="1.0"/>
				<mu2 value="1.0"/>
				<slip1 value="0.01"/>
				<slip2 value="0.01"/>
			</gazebo>
			<geometry>
				<box size="6.288625e-02 6.288625e-02 6.030000e-02"/>
			</geometry>
		</collision>
		<visual name="component_RLFFRFRFR_ActiveHinge__frame_visual">
			<origin xyz="7.074313e-02 -5.406813e-02 0.000000e+00" rpy="0.000000e+00 0.000000e+00 -1.570796e+00"/>
			<material name="no_texture">
				<color rgba="1 0.08 0.58 1.0"/>
			</material>
			<geometry>
				<mesh filename="package://models/rg_robot/meshes/ActiveHinge_Frame.dae"/>
			</geometry>
		</visual>
		<collision name="component_RLFFRFRFR_ActiveHinge__frame_collision">
			<origin xyz="7.074313e-02 -5.406813e-02 0.000000e+00" rpy="0.000000e+00 0.000000e+00 -1.570796e+00"/>
			<contact>
				<lateral_friction value="0.8"/>
				<rolling_friction value="0"/>
				<spinning_friction value="1"/>
				<stiffness value="90000"/>
				<damping value="3333333.3333333335"/>
			</contact>
			<gazebo name="component_RLFFRFRFR_ActiveHinge__frame">
				<mu1 value="1.0"/>
				<mu2 value="1.0"/>
				<slip1 value="0.01"/>
				<slip2 value="0.01"/>
			</gazebo>
			<geometry>
				<box size="4.525000e-02 5.300000e-02 1.658910e-02"/>
			</geometry>
		</collision>
		<visual name="component_RLFFRFRFL_ActiveHinge__frame_visual">
			<origin xyz="7.074313e-02 5.406812e-02 -1.255940e-18" rpy="1.570796e+00 5.551115e-17 1.570796e+00"/>
			<material name="no_texture">
				<color rgba="0.7 0 0 1.0"/>
			</material>
			<geometry>
				<mesh filename="package://models/rg_robot/meshes/ActiveHinge_Frame.dae"/>
			</geometry>
		</visual>
		<collision name="component_RLFFRFRFL_ActiveHinge__frame_collision">
			<origin xyz="7.074313e-02 5.406812e-02 -1.255940e-18" rpy="1.570796e+00 5.551115e-17 1.570796e+00"/>
			<contact>
				<lateral_friction value="0.8"/>
				<rolling_friction value="0"/>
				<spinning_friction value="1"/>
				<stiffness value="90000"/>
				<damping value="3333333.3333333335"/>
			</contact>
			<gazebo name="component_RLFFRFRFL_ActiveHinge__frame">
				<mu1 value="1.0"/>
				<mu2 value="1.0"/>
				<slip1 value="0.01"/>
				<slip2 value="0.01"/>
			</gazebo>
			<geometry>
				<box size="4.525000e-02 5.300000e-02 1.658910e-02"/>
			</geometry>
		</collision>
		<inertial>
			<origin xyz="3.879402e-02 -9.856383e-19 -1.255940e-19" rpy="0.000000e+00 -0.000000e+00 0.000000e+00"/>
			<mass value="0.10999999999999999"/>
			<inertia ixx="0.00010447556616890915" ixy="3.3881317890172014e-21" ixz="1.8059570080617334e-21" iyy="0.00014365918047989695" iyz="1.299194471666755e-21" izz="0.0002204332665443211"/>
		</inertial>
	</link>
	<link name="RLFFRFRFR_Leg">
		<origin xyz="1.015000e-02 0.000000e+00 0.000000e+00" rpy="0.000000e+00 -0.000000e+00 0.000000e+00"/>
		<visual name="component_RLFFRFRFR_ActiveHinge__servo_visual">
			<origin xyz="2.990000e-02 0.000000e+00 0.000000e+00" rpy="0.000000e+00 -0.000000e+00 0.000000e+00"/>
			<material name="no_texture">
				<color rgba="1 0.08 0.58 1.0"/>
			</material>
			<geometry>
				<mesh filename="package://models/rg_robot/meshes/ActiveCardanHinge_Servo_Holder.dae"/>
			</geometry>
		</visual>
		<collision name="component_RLFFRFRFR_ActiveHinge__servo_collision">
			<origin xyz="1.015000e-02 0.000000e+00 0.000000e+00" rpy="0.000000e+00 -0.000000e+00 0.000000e+00"/>
			<contact>
				<lateral_friction value="0.8"/>
				<rolling_friction value="0"/>
				<spinning_friction value="1"/>
				<stiffness value="90000"/>
				<damping value="3333333.3333333335"/>
			</contact>
			<gazebo name="component_RLFFRFRFR_ActiveHinge__servo">
				<mu1 value="1.0"/>
				<mu2 value="1.0"/>
				<slip1 value="0.01"/>
				<slip2 value="0.01"/>
			</gazebo>
			<geometry>
				<box size="5.830000e-02 5.120000e-02 2.000000e-02"/>
			</geometry>
		</collision>
		<collision name="component_RLFFRFRFR_ActiveHinge__servo2_collision">
			<origin xyz="3.830000e-02 0.000000e+00 0.000000e+00" rpy="0.000000e+00 -0.000000e+00 0.000000e+00"/>
			<contact>
				<lateral_friction value="0.8"/>
				<rolling_friction value="0"/>
				<spinning_friction value="1"/>
				<stiffness value="90000"/>
				<damping value="3333333.3333333335"/>
			</contact>
			<gazebo name="component_RLFFRFRFR_ActiveHinge__servo2">
				<mu1 value="1.0"/>
				<mu2 value="1.0"/>
				<slip1 value="0.01"/>
				<slip2 value="0.01"/>
			</gazebo>
			<geometry>
				<box size="2.000000e-03 5.300000e-02 5.300000e-02"/>
			</geometry>
		</collision>
		<inertial>
			<origin xyz="1.015000e-02 0.000000e+00 0.000000e+00" rpy="0.000000e+00 -0.000000e+00 0.000000e+00"/>
			<mass value="0.058"/>
			<inertia ixx="1.460362666666667e-05" ixy="0.0" ixz="0.0" iyy="1.836130166666667e-05" iyz="0.0" izz="2.909826166666667e-05"/>
		</inertial>
	</link>
	<link name="RLFFRFRFL_Leg">
		<origin xyz="1.840399e-02 0.000000e+00 0.000000e+00" rpy="0.000000e+00 -0.000000e+00 0.000000e+00"/>
		<visual name="component_RLFFRFRFL_ActiveHinge__servo_visual">
			<origin xyz="2.990000e-02 0.000000e+00 0.000000e+00" rpy="0.000000e+00 -0.000000e+00 0.000000e+00"/>
			<material name="no_texture">
				<color rgba="0.7 0 0 1.0"/>
			</material>
			<geometry>
				<mesh filename="package://models/rg_robot/meshes/ActiveCardanHinge_Servo_Holder.dae"/>
			</geometry>
		</visual>
		<collision name="component_RLFFRFRFL_ActiveHinge__servo_collision">
			<origin xyz="1.015000e-02 0.000000e+00 0.000000e+00" rpy="0.000000e+00 -0.000000e+00 0.000000e+00"/>
			<contact>
				<lateral_friction value="0.8"/>
				<rolling_friction value="0"/>
				<spinning_friction value="1"/>
				<stiffness value="90000"/>
				<damping value="3333333.3333333335"/>
			</contact>
			<gazebo name="component_RLFFRFRFL_ActiveHinge__servo">
				<mu1 value="1.0"/>
				<mu2 value="1.0"/>
				<slip1 value="0.01"/>
				<slip2 value="0.01"/>
			</gazebo>
			<geometry>
				<box size="5.830000e-02 5.120000e-02 2.000000e-02"/>
			</geometry>
		</collision>
		<collision name="component_RLFFRFRFL_ActiveHinge__servo2_collision">
			<origin xyz="3.830000e-02 0.000000e+00 0.000000e+00" rpy="0.000000e+00 -0.000000e+00 0.000000e+00"/>
			<contact>
				<lateral_friction value="0.8"/>
				<rolling_friction value="0"/>
				<spinning_friction value="1"/>
				<stiffness value="90000"/>
				<damping value="3333333.3333333335"/>
			</contact>
			<gazebo name="component_RLFFRFRFL_ActiveHinge__servo2">
				<mu1 value="1.0"/>
				<mu2 value="1.0"/>
				<slip1 value="0.01"/>
				<slip2 value="0.01"/>
			</gazebo>
			<geometry>
				<box size="2.000000e-03 5.300000e-02 5.300000e-02"/>
			</geometry>
		</collision>
		<visual name="component_RLFFRFRFLF_ActiveHinge__frame_visual">
			<origin xyz="6.192500e-02 0.000000e+00 0.000000e+00" rpy="-1.570796e+00 0.000000e+00 0.000000e+00"/>
			<material name="no_texture">
				<color rgba="1 0.08 0.58 1.0"/>
			</material>
			<geometry>
				<mesh filename="package://models/rg_robot/meshes/ActiveHinge_Frame.dae"/>
			</geometry>
		</visual>
		<collision name="component_RLFFRFRFLF_ActiveHinge__frame_collision">
			<origin xyz="6.192500e-02 0.000000e+00 0.000000e+00" rpy="-1.570796e+00 0.000000e+00 0.000000e+00"/>
			<contact>
				<lateral_friction value="0.8"/>
				<rolling_friction value="0"/>
				<spinning_friction value="1"/>
				<stiffness value="90000"/>
				<damping value="3333333.3333333335"/>
			</contact>
			<gazebo name="component_RLFFRFRFLF_ActiveHinge__frame">
				<mu1 value="1.0"/>
				<mu2 value="1.0"/>
				<slip1 value="0.01"/>
				<slip2 value="0.01"/>
			</gazebo>
			<geometry>
				<box size="4.525000e-02 5.300000e-02 1.658910e-02"/>
			</geometry>
		</collision>
		<inertial>
			<origin xyz="1.840399e-02 0.000000e+00 0.000000e+00" rpy="0.000000e+00 -0.000000e+00 0.000000e+00"/>
			<mass value="0.069"/>
			<inertia ixx="1.7430808385575836e-05" ixy="0.0" ixz="0.0" iyy="4.759945640398551e-05" iyz="0.0" izz="5.601376478956134e-05"/>
		</inertial>
	</link>
	<link name="RLFFRFRFLF_Leg">
		<origin xyz="1.840399e-02 0.000000e+00 0.000000e+00" rpy="0.000000e+00 -0.000000e+00 0.000000e+00"/>
		<visual name="component_RLFFRFRFLF_ActiveHinge__servo_visual">
			<origin xyz="2.990000e-02 0.000000e+00 0.000000e+00" rpy="0.000000e+00 -0.000000e+00 0.000000e+00"/>
			<material name="no_texture">
				<color rgba="1 0.08 0.58 1.0"/>
			</material>
			<geometry>
				<mesh filename="package://models/rg_robot/meshes/ActiveCardanHinge_Servo_Holder.dae"/>
			</geometry>
		</visual>
		<collision name="component_RLFFRFRFLF_ActiveHinge__servo_collision">
			<origin xyz="1.015000e-02 0.000000e+00 0.000000e+00" rpy="0.000000e+00 -0.000000e+00 0.000000e+00"/>
			<contact>
				<lateral_friction value="0.8"/>
				<rolling_friction value="0"/>
				<spinning_friction value="1"/>
				<stiffness value="90000"/>
				<damping value="3333333.3333333335"/>
			</contact>
			<gazebo name="component_RLFFRFRFLF_ActiveHinge__servo">
				<mu1 value="1.0"/>
				<mu2 value="1.0"/>
				<slip1 value="0.01"/>
				<slip2 value="0.01"/>
			</gazebo>
			<geometry>
				<box size="5.830000e-02 5.120000e-02 2.000000e-02"/>
			</geometry>
		</collision>
		<collision name="component_RLFFRFRFLF_ActiveHinge__servo2_collision">
			<origin xyz="3.830000e-02 0.000000e+00 0.000000e+00" rpy="0.000000e+00 -0.000000e+00 0.000000e+00"/>
			<contact>
				<lateral_friction value="0.8"/>
				<rolling_friction value="0"/>
				<spinning_friction value="1"/>
				<stiffness value="90000"/>
				<damping value="3333333.3333333335"/>
			</contact>
			<gazebo name="component_RLFFRFRFLF_ActiveHinge__servo2">
				<mu1 value="1.0"/>
				<mu2 value="1.0"/>
				<slip1 value="0.01"/>
				<slip2 value="0.01"/>
			</gazebo>
			<geometry>
				<box size="2.000000e-03 5.300000e-02 5.300000e-02"/>
			</geometry>
		</collision>
		<visual name="component_RLFFRFRFLFF_ActiveHinge__frame_visual">
			<origin xyz="6.192500e-02 0.000000e+00 0.000000e+00" rpy="0.000000e+00 -0.000000e+00 0.000000e+00"/>
			<material name="no_texture">
				<color rgba="1 0.08 0.58 1.0"/>
			</material>
			<geometry>
				<mesh filename="package://models/rg_robot/meshes/ActiveHinge_Frame.dae"/>
			</geometry>
		</visual>
		<collision name="component_RLFFRFRFLFF_ActiveHinge__frame_collision">
			<origin xyz="6.192500e-02 0.000000e+00 0.000000e+00" rpy="0.000000e+00 -0.000000e+00 0.000000e+00"/>
			<contact>
				<lateral_friction value="0.8"/>
				<rolling_friction value="0"/>
				<spinning_friction value="1"/>
				<stiffness value="90000"/>
				<damping value="3333333.3333333335"/>
			</contact>
			<gazebo name="component_RLFFRFRFLFF_ActiveHinge__frame">
				<mu1 value="1.0"/>
				<mu2 value="1.0"/>
				<slip1 value="0.01"/>
				<slip2 value="0.01"/>
			</gazebo>
			<geometry>
				<box size="4.525000e-02 5.300000e-02 1.658910e-02"/>
			</geometry>
		</collision>
		<inertial>
			<origin xyz="1.840399e-02 0.000000e+00 0.000000e+00" rpy="0.000000e+00 -0.000000e+00 0.000000e+00"/>
			<mass value="0.069"/>
			<inertia ixx="1.7430808385575836e-05" ixy="0.0" ixz="0.0" iyy="4.5276804789561346e-05" iyz="0.0" izz="5.83364164039855e-05"/>
		</inertial>
	</link>
	<link name="RLFFRFRFLFF_Leg">
		<origin xyz="1.840399e-02 0.000000e+00 0.000000e+00" rpy="0.000000e+00 -0.000000e+00 0.000000e+00"/>
		<visual name="component_RLFFRFRFLFF_ActiveHinge__servo_visual">
			<origin xyz="2.990000e-02 0.000000e+00 0.000000e+00" rpy="0.000000e+00 -0.000000e+00 0.000000e+00"/>
			<material name="no_texture">
				<color rgba="1 0.08 0.58 1.0"/>
			</material>
			<geometry>
				<mesh filename="package://models/rg_robot/meshes/ActiveCardanHinge_Servo_Holder.dae"/>
			</geometry>
		</visual>
		<collision name="component_RLFFRFRFLFF_ActiveHinge__servo_collision">
			<origin xyz="1.015000e-02 0.000000e+00 0.000000e+00" rpy="0.000000e+00 -0.000000e+00 0.000000e+00"/>
			<contact>
				<lateral_friction value="0.8"/>
				<rolling_friction value="0"/>
				<spinning_friction value="1"/>
				<stiffness value="90000"/>
				<damping value="3333333.3333333335"/>
			</contact>
			<gazebo name="component_RLFFRFRFLFF_ActiveHinge__servo">
				<mu1 value="1.0"/>
				<mu2 value="1.0"/>
				<slip1 value="0.01"/>
				<slip2 value="0.01"/>
			</gazebo>
			<geometry>
				<box size="5.830000e-02 5.120000e-02 2.000000e-02"/>
			</geometry>
		</collision>
		<collision name="component_RLFFRFRFLFF_ActiveHinge__servo2_collision">
			<origin xyz="3.830000e-02 0.000000e+00 0.000000e+00" rpy="0.000000e+00 -0.000000e+00 0.000000e+00"/>
			<contact>
				<lateral_friction value="0.8"/>
				<rolling_friction value="0"/>
				<spinning_friction value="1"/>
				<stiffness value="90000"/>
				<damping value="3333333.3333333335"/>
			</contact>
			<gazebo name="component_RLFFRFRFLFF_ActiveHinge__servo2">
				<mu1 value="1.0"/>
				<mu2 value="1.0"/>
				<slip1 value="0.01"/>
				<slip2 value="0.01"/>
			</gazebo>
			<geometry>
				<box size="2.000000e-03 5.300000e-02 5.300000e-02"/>
			</geometry>
		</collision>
		<visual name="component_RLFFRFRFLFFF_ActiveHinge__frame_visual">
			<origin xyz="6.192500e-02 0.000000e+00 0.000000e+00" rpy="0.000000e+00 -0.000000e+00 0.000000e+00"/>
			<material name="no_texture">
				<color rgba="1 0.08 0.58 1.0"/>
			</material>
			<geometry>
				<mesh filename="package://models/rg_robot/meshes/ActiveHinge_Frame.dae"/>
			</geometry>
		</visual>
		<collision name="component_RLFFRFRFLFFF_ActiveHinge__frame_collision">
			<origin xyz="6.192500e-02 0.000000e+00 0.000000e+00" rpy="0.000000e+00 -0.000000e+00 0.000000e+00"/>
			<contact>
				<lateral_friction value="0.8"/>
				<rolling_friction value="0"/>
				<spinning_friction value="1"/>
				<stiffness value="90000"/>
				<damping value="3333333.3333333335"/>
			</contact>
			<gazebo name="component_RLFFRFRFLFFF_ActiveHinge__frame">
				<mu1 value="1.0"/>
				<mu2 value="1.0"/>
				<slip1 value="0.01"/>
				<slip2 value="0.01"/>
			</gazebo>
			<geometry>
				<box size="4.525000e-02 5.300000e-02 1.658910e-02"/>
			</geometry>
		</collision>
		<inertial>
			<origin xyz="1.840399e-02 0.000000e+00 0.000000e+00" rpy="0.000000e+00 -0.000000e+00 0.000000e+00"/>
			<mass value="0.069"/>
			<inertia ixx="1.7430808385575836e-05" ixy="0.0" ixz="0.0" iyy="4.5276804789561346e-05" iyz="0.0" izz="5.83364164039855e-05"/>
		</inertial>
	</link>
	<link name="RLFFRFRFLFFF_Leg">
		<origin xyz="1.015000e-02 0.000000e+00 0.000000e+00" rpy="0.000000e+00 -0.000000e+00 0.000000e+00"/>
		<visual name="component_RLFFRFRFLFFF_ActiveHinge__servo_visual">
			<origin xyz="2.990000e-02 0.000000e+00 0.000000e+00" rpy="0.000000e+00 -0.000000e+00 0.000000e+00"/>
			<material name="no_texture">
				<color rgba="1 0.08 0.58 1.0"/>
			</material>
			<geometry>
				<mesh filename="package://models/rg_robot/meshes/ActiveCardanHinge_Servo_Holder.dae"/>
			</geometry>
		</visual>
		<collision name="component_RLFFRFRFLFFF_ActiveHinge__servo_collision">
			<origin xyz="1.015000e-02 0.000000e+00 0.000000e+00" rpy="0.000000e+00 -0.000000e+00 0.000000e+00"/>
			<contact>
				<lateral_friction value="0.8"/>
				<rolling_friction value="0"/>
				<spinning_friction value="1"/>
				<stiffness value="90000"/>
				<damping value="3333333.3333333335"/>
			</contact>
			<gazebo name="component_RLFFRFRFLFFF_ActiveHinge__servo">
				<mu1 value="1.0"/>
				<mu2 value="1.0"/>
				<slip1 value="0.01"/>
				<slip2 value="0.01"/>
			</gazebo>
			<geometry>
				<box size="5.830000e-02 5.120000e-02 2.000000e-02"/>
			</geometry>
		</collision>
		<collision name="component_RLFFRFRFLFFF_ActiveHinge__servo2_collision">
			<origin xyz="3.830000e-02 0.000000e+00 0.000000e+00" rpy="0.000000e+00 -0.000000e+00 0.000000e+00"/>
			<contact>
				<lateral_friction value="0.8"/>
				<rolling_friction value="0"/>
				<spinning_friction value="1"/>
				<stiffness value="90000"/>
				<damping value="3333333.3333333335"/>
			</contact>
			<gazebo name="component_RLFFRFRFLFFF_ActiveHinge__servo2">
				<mu1 value="1.0"/>
				<mu2 value="1.0"/>
				<slip1 value="0.01"/>
				<slip2 value="0.01"/>
			</gazebo>
			<geometry>
				<box size="2.000000e-03 5.300000e-02 5.300000e-02"/>
			</geometry>
		</collision>
		<inertial>
			<origin xyz="1.015000e-02 0.000000e+00 0.000000e+00" rpy="0.000000e+00 -0.000000e+00 0.000000e+00"/>
			<mass value="0.058"/>
			<inertia ixx="1.460362666666667e-05" ixy="0.0" ixz="0.0" iyy="1.836130166666667e-05" iyz="0.0" izz="2.909826166666667e-05"/>
		</inertial>
	</link>
	<link name="RLFFRFL_Leg">
		<origin xyz="1.840399e-02 0.000000e+00 0.000000e+00" rpy="0.000000e+00 -0.000000e+00 0.000000e+00"/>
		<visual name="component_RLFFRFL_ActiveHinge__servo_visual">
			<origin xyz="2.990000e-02 0.000000e+00 0.000000e+00" rpy="0.000000e+00 -0.000000e+00 0.000000e+00"/>
			<material name="no_texture">
				<color rgba="0.7 0 0 1.0"/>
			</material>
			<geometry>
				<mesh filename="package://models/rg_robot/meshes/ActiveCardanHinge_Servo_Holder.dae"/>
			</geometry>
		</visual>
		<collision name="component_RLFFRFL_ActiveHinge__servo_collision">
			<origin xyz="1.015000e-02 0.000000e+00 0.000000e+00" rpy="0.000000e+00 -0.000000e+00 0.000000e+00"/>
			<contact>
				<lateral_friction value="0.8"/>
				<rolling_friction value="0"/>
				<spinning_friction value="1"/>
				<stiffness value="90000"/>
				<damping value="3333333.3333333335"/>
			</contact>
			<gazebo name="component_RLFFRFL_ActiveHinge__servo">
				<mu1 value="1.0"/>
				<mu2 value="1.0"/>
				<slip1 value="0.01"/>
				<slip2 value="0.01"/>
			</gazebo>
			<geometry>
				<box size="5.830000e-02 5.120000e-02 2.000000e-02"/>
			</geometry>
		</collision>
		<collision name="component_RLFFRFL_ActiveHinge__servo2_collision">
			<origin xyz="3.830000e-02 0.000000e+00 0.000000e+00" rpy="0.000000e+00 -0.000000e+00 0.000000e+00"/>
			<contact>
				<lateral_friction value="0.8"/>
				<rolling_friction value="0"/>
				<spinning_friction value="1"/>
				<stiffness value="90000"/>
				<damping value="3333333.3333333335"/>
			</contact>
			<gazebo name="component_RLFFRFL_ActiveHinge__servo2">
				<mu1 value="1.0"/>
				<mu2 value="1.0"/>
				<slip1 value="0.01"/>
				<slip2 value="0.01"/>
			</gazebo>
			<geometry>
				<box size="2.000000e-03 5.300000e-02 5.300000e-02"/>
			</geometry>
		</collision>
		<visual name="component_RLFFRFLF_ActiveHinge__frame_visual">
			<origin xyz="6.192500e-02 0.000000e+00 0.000000e+00" rpy="-1.570796e+00 0.000000e+00 0.000000e+00"/>
			<material name="no_texture">
				<color rgba="1 0.08 0.58 1.0"/>
			</material>
			<geometry>
				<mesh filename="package://models/rg_robot/meshes/ActiveHinge_Frame.dae"/>
			</geometry>
		</visual>
		<collision name="component_RLFFRFLF_ActiveHinge__frame_collision">
			<origin xyz="6.192500e-02 0.000000e+00 0.000000e+00" rpy="-1.570796e+00 0.000000e+00 0.000000e+00"/>
			<contact>
				<lateral_friction value="0.8"/>
				<rolling_friction value="0"/>
				<spinning_friction value="1"/>
				<stiffness value="90000"/>
				<damping value="3333333.3333333335"/>
			</contact>
			<gazebo name="component_RLFFRFLF_ActiveHinge__frame">
				<mu1 value="1.0"/>
				<mu2 value="1.0"/>
				<slip1 value="0.01"/>
				<slip2 value="0.01"/>
			</gazebo>
			<geometry>
				<box size="4.525000e-02 5.300000e-02 1.658910e-02"/>
			</geometry>
		</collision>
		<inertial>
			<origin xyz="1.840399e-02 0.000000e+00 0.000000e+00" rpy="0.000000e+00 -0.000000e+00 0.000000e+00"/>
			<mass value="0.069"/>
			<inertia ixx="1.7430808385575836e-05" ixy="0.0" ixz="0.0" iyy="4.759945640398551e-05" iyz="0.0" izz="5.601376478956134e-05"/>
		</inertial>
	</link>
	<link name="RLFFRFLF_Leg">
		<origin xyz="1.015000e-02 0.000000e+00 0.000000e+00" rpy="0.000000e+00 -0.000000e+00 0.000000e+00"/>
		<visual name="component_RLFFRFLF_ActiveHinge__servo_visual">
			<origin xyz="2.990000e-02 0.000000e+00 0.000000e+00" rpy="0.000000e+00 -0.000000e+00 0.000000e+00"/>
			<material name="no_texture">
				<color rgba="1 0.08 0.58 1.0"/>
			</material>
			<geometry>
				<mesh filename="package://models/rg_robot/meshes/ActiveCardanHinge_Servo_Holder.dae"/>
			</geometry>
		</visual>
		<collision name="component_RLFFRFLF_ActiveHinge__servo_collision">
			<origin xyz="1.015000e-02 0.000000e+00 0.000000e+00" rpy="0.000000e+00 -0.000000e+00 0.000000e+00"/>
			<contact>
				<lateral_friction value="0.8"/>
				<rolling_friction value="0"/>
				<spinning_friction value="1"/>
				<stiffness value="90000"/>
				<damping value="3333333.3333333335"/>
			</contact>
			<gazebo name="component_RLFFRFLF_ActiveHinge__servo">
				<mu1 value="1.0"/>
				<mu2 value="1.0"/>
				<slip1 value="0.01"/>
				<slip2 value="0.01"/>
			</gazebo>
			<geometry>
				<box size="5.830000e-02 5.120000e-02 2.000000e-02"/>
			</geometry>
		</collision>
		<collision name="component_RLFFRFLF_ActiveHinge__servo2_collision">
			<origin xyz="3.830000e-02 0.000000e+00 0.000000e+00" rpy="0.000000e+00 -0.000000e+00 0.000000e+00"/>
			<contact>
				<lateral_friction value="0.8"/>
				<rolling_friction value="0"/>
				<spinning_friction value="1"/>
				<stiffness value="90000"/>
				<damping value="3333333.3333333335"/>
			</contact>
			<gazebo name="component_RLFFRFLF_ActiveHinge__servo2">
				<mu1 value="1.0"/>
				<mu2 value="1.0"/>
				<slip1 value="0.01"/>
				<slip2 value="0.01"/>
			</gazebo>
			<geometry>
				<box size="2.000000e-03 5.300000e-02 5.300000e-02"/>
			</geometry>
		</collision>
		<inertial>
			<origin xyz="1.015000e-02 0.000000e+00 0.000000e+00" rpy="0.000000e+00 -0.000000e+00 0.000000e+00"/>
			<mass value="0.058"/>
			<inertia ixx="1.460362666666667e-05" ixy="0.0" ixz="0.0" iyy="1.836130166666667e-05" iyz="0.0" izz="2.909826166666667e-05"/>
		</inertial>
	</link>
	<link name="RLFFL_Leg">
		<origin xyz="1.015000e-02 0.000000e+00 0.000000e+00" rpy="0.000000e+00 -0.000000e+00 0.000000e+00"/>
		<visual name="component_RLFFL_ActiveHinge__servo_visual">
			<origin xyz="2.990000e-02 0.000000e+00 0.000000e+00" rpy="0.000000e+00 -0.000000e+00 0.000000e+00"/>
			<material name="no_texture">
				<color rgba="0.7 0 0 1.0"/>
			</material>
			<geometry>
				<mesh filename="package://models/rg_robot/meshes/ActiveCardanHinge_Servo_Holder.dae"/>
			</geometry>
		</visual>
		<collision name="component_RLFFL_ActiveHinge__servo_collision">
			<origin xyz="1.015000e-02 0.000000e+00 0.000000e+00" rpy="0.000000e+00 -0.000000e+00 0.000000e+00"/>
			<contact>
				<lateral_friction value="0.8"/>
				<rolling_friction value="0"/>
				<spinning_friction value="1"/>
				<stiffness value="90000"/>
				<damping value="3333333.3333333335"/>
			</contact>
			<gazebo name="component_RLFFL_ActiveHinge__servo">
				<mu1 value="1.0"/>
				<mu2 value="1.0"/>
				<slip1 value="0.01"/>
				<slip2 value="0.01"/>
			</gazebo>
			<geometry>
				<box size="5.830000e-02 5.120000e-02 2.000000e-02"/>
			</geometry>
		</collision>
		<collision name="component_RLFFL_ActiveHinge__servo2_collision">
			<origin xyz="3.830000e-02 0.000000e+00 0.000000e+00" rpy="0.000000e+00 -0.000000e+00 0.000000e+00"/>
			<contact>
				<lateral_friction value="0.8"/>
				<rolling_friction value="0"/>
				<spinning_friction value="1"/>
				<stiffness value="90000"/>
				<damping value="3333333.3333333335"/>
			</contact>
			<gazebo name="component_RLFFL_ActiveHinge__servo2">
				<mu1 value="1.0"/>
				<mu2 value="1.0"/>
				<slip1 value="0.01"/>
				<slip2 value="0.01"/>
			</gazebo>
			<geometry>
				<box size="2.000000e-03 5.300000e-02 5.300000e-02"/>
			</geometry>
		</collision>
		<inertial>
			<origin xyz="1.015000e-02 0.000000e+00 0.000000e+00" rpy="0.000000e+00 -0.000000e+00 0.000000e+00"/>
			<mass value="0.058"/>
			<inertia ixx="1.460362666666667e-05" ixy="0.0" ixz="0.0" iyy="1.836130166666667e-05" iyz="0.0" izz="2.909826166666667e-05"/>
		</inertial>
	</link>
	<gazebo>
		<plugin name="robot_controller" filename="libRobotControlPlugin.so">
			<rv:robot_config xmlns:rv="https://github.com/ci-group/revolve">
				<rv:update_rate>8.000000e+00</rv:update_rate>
				<rv:brain>
					<rv:learner type="de" subtype="revde" CR="0.9" F="0.5" n_parents="3" verbose="false" population_size="20" max_eval="300"/>
					<rv:learner type="de" subtype="revde" CR="0.9" F="0.5" n_parents="3" verbose="false" population_size="20" max_eval="300"/>
					<rv:IMC active="false" restore_checkpoint="false" save_checkpoint="true" learning_rate="5e-2;" beta1="0.9;" beta2="0.99;" weight_decay="0.001;"/>
					<rv:sensors>
						<rv:sensor link="Core" sensor="core-imu_sensor" type="imu" id="Core_sensor" part_id="module0"/>
					</rv:sensors>
					<rv:actuators>
						<rv:servomotor type="position" id="module2__rotate" part_id="module2" part_name="component_RR_ActiveHinge__joint" joint="component_RR_ActiveHinge__joint" coordinates="-1.0;1.0;0.0">
							<rv:pid>
								<rv:p>1.000000e+00</rv:p>
								<rv:i>0.000000e+00</rv:i>
								<rv:d>0.000000e+00</rv:d>
								<rv:i_max>0.000000e+00</rv:i_max>
								<rv:i_min>0.000000e+00</rv:i_min>
							</rv:pid>
						</rv:servomotor>
						<rv:servomotor type="position" id="module3__rotate" part_id="module3" part_name="component_RL_ActiveHinge__joint" joint="component_RL_ActiveHinge__joint" coordinates="1.0;1.0;0.0">
							<rv:pid>
								<rv:p>1.000000e+00</rv:p>
								<rv:i>0.000000e+00</rv:i>
								<rv:d>0.000000e+00</rv:d>
								<rv:i_max>0.000000e+00</rv:i_max>
								<rv:i_min>0.000000e+00</rv:i_min>
							</rv:pid>
						</rv:servomotor>
						<rv:servomotor type="position" id="module4__rotate" part_id="module4" part_name="component_RLF_ActiveHinge__joint" joint="component_RLF_ActiveHinge__joint" coordinates="2.0;1.0;0.0">
							<rv:pid>
								<rv:p>1.000000e+00</rv:p>
								<rv:i>0.000000e+00</rv:i>
								<rv:d>0.000000e+00</rv:d>
								<rv:i_max>0.000000e+00</rv:i_max>
								<rv:i_min>0.000000e+00</rv:i_min>
							</rv:pid>
						</rv:servomotor>
						<rv:servomotor type="position" id="module6__rotate" part_id="module6" part_name="component_RLFFR_ActiveHinge__joint" joint="component_RLFFR_ActiveHinge__joint" coordinates="3.0;2.0;0.0">
							<rv:pid>
								<rv:p>1.000000e+00</rv:p>
								<rv:i>0.000000e+00</rv:i>
								<rv:d>0.000000e+00</rv:d>
								<rv:i_max>0.000000e+00</rv:i_max>
								<rv:i_min>0.000000e+00</rv:i_min>
							</rv:pid>
						</rv:servomotor>
						<rv:servomotor type="position" id="module11__rotate" part_id="module11" part_name="component_RLFFRFR_ActiveHinge__joint" joint="component_RLFFRFR_ActiveHinge__joint" coordinates="2.0;3.0;0.0">
							<rv:pid>
								<rv:p>1.000000e+00</rv:p>
								<rv:i>0.000000e+00</rv:i>
								<rv:d>0.000000e+00</rv:d>
								<rv:i_max>0.000000e+00</rv:i_max>
								<rv:i_min>0.000000e+00</rv:i_min>
							</rv:pid>
						</rv:servomotor>
						<rv:servomotor type="position" id="module15__rotate" part_id="module15" part_name="component_RLFFRFRFR_ActiveHinge__joint" joint="component_RLFFRFRFR_ActiveHinge__joint" coordinates="1.0;2.0;0.0">
							<rv:pid>
								<rv:p>1.000000e+00</rv:p>
								<rv:i>0.000000e+00</rv:i>
								<rv:d>0.000000e+00</rv:d>
								<rv:i_max>0.000000e+00</rv:i_max>
								<rv:i_min>0.000000e+00</rv:i_min>
							</rv:pid>
						</rv:servomotor>
						<rv:servomotor type="position" id="module16__rotate" part_id="module16" part_name="component_RLFFRFRFL_ActiveHinge__joint" joint="component_RLFFRFRFL_ActiveHinge__joint" coordinates="1.0;4.0;0.0">
							<rv:pid>
								<rv:p>1.000000e+00</rv:p>
								<rv:i>0.000000e+00</rv:i>
								<rv:d>0.000000e+00</rv:d>
								<rv:i_max>0.000000e+00</rv:i_max>
								<rv:i_min>0.000000e+00</rv:i_min>
							</rv:pid>
						</rv:servomotor>
						<rv:servomotor type="position" id="module17__rotate" part_id="module17" part_name="component_RLFFRFRFLF_ActiveHinge__joint" joint="component_RLFFRFRFLF_ActiveHinge__joint" coordinates="1.0;5.0;0.0">
							<rv:pid>
								<rv:p>1.000000e+00</rv:p>
								<rv:i>0.000000e+00</rv:i>
								<rv:d>0.000000e+00</rv:d>
								<rv:i_max>0.000000e+00</rv:i_max>
								<rv:i_min>0.000000e+00</rv:i_min>
							</rv:pid>
						</rv:servomotor>
						<rv:servomotor type="position" id="module18__rotate" part_id="module18" part_name="component_RLFFRFRFLFF_ActiveHinge__joint" joint="component_RLFFRFRFLFF_ActiveHinge__joint" coordinates="1.0;6.0;0.0">
							<rv:pid>
								<rv:p>1.000000e+00</rv:p>
								<rv:i>0.000000e+00</rv:i>
								<rv:d>0.000000e+00</rv:d>
								<rv:i_max>0.000000e+00</rv:i_max>
								<rv:i_min>0.000000e+00</rv:i_min>
							</rv:pid>
						</rv:servomotor>
						<rv:servomotor type="position" id="module19__rotate" part_id="module19" part_name="component_RLFFRFRFLFFF_ActiveHinge__joint" joint="component_RLFFRFRFLFFF_ActiveHinge__joint" coordinates="1.0;7.0;0.0">
							<rv:pid>
								<rv:p>1.000000e+00</rv:p>
								<rv:i>0.000000e+00</rv:i>
								<rv:d>0.000000e+00</rv:d>
								<rv:i_max>0.000000e+00</rv:i_max>
								<rv:i_min>0.000000e+00</rv:i_min>
							</rv:pid>
						</rv:servomotor>
						<rv:servomotor type="position" id="module12__rotate" part_id="module12" part_name="component_RLFFRFL_ActiveHinge__joint" joint="component_RLFFRFL_ActiveHinge__joint" coordinates="4.0;3.0;0.0">
							<rv:pid>
								<rv:p>1.000000e+00</rv:p>
								<rv:i>0.000000e+00</rv:i>
								<rv:d>0.000000e+00</rv:d>
								<rv:i_max>0.000000e+00</rv:i_max>
								<rv:i_min>0.000000e+00</rv:i_min>
							</rv:pid>
						</rv:servomotor>
						<rv:servomotor type="position" id="module13__rotate" part_id="module13" part_name="component_RLFFRFLF_ActiveHinge__joint" joint="component_RLFFRFLF_ActiveHinge__joint" coordinates="5.0;3.0;0.0">
							<rv:pid>
								<rv:p>1.000000e+00</rv:p>
								<rv:i>0.000000e+00</rv:i>
								<rv:d>0.000000e+00</rv:d>
								<rv:i_max>0.000000e+00</rv:i_max>
								<rv:i_min>0.000000e+00</rv:i_min>
							</rv:pid>
						</rv:servomotor>
						<rv:servomotor type="position" id="module7__rotate" part_id="module7" part_name="component_RLFFL_ActiveHinge__joint" joint="component_RLFFL_ActiveHinge__joint" coordinates="3.0;0.0;0.0">
							<rv:pid>
								<rv:p>1.000000e+00</rv:p>
								<rv:i>0.000000e+00</rv:i>
								<rv:d>0.000000e+00</rv:d>
								<rv:i_max>0.000000e+00</rv:i_max>
								<rv:i_min>0.000000e+00</rv:i_min>
							</rv:pid>
						</rv:servomotor>
					</rv:actuators>
				</rv:brain>
			</rv:robot_config>
		</plugin>
	</gazebo>
</robot>
