<?xml version="1.0" ?>
<!-- Robot -->
 <robot name="thymio">
    <link name="chassis">
      <origin xyz="0 0 0.5" rpy="0 0 0"/>
      <inertial>
        <origin xyz="0.02 0 -.01" rpy="0 0 0"/>
        <mass value="0.270"/>
        <inertia ixx="1.272320e-04" ixy="-1.138297e-06" ixz="-1.762013e-21" iyy="1.260759e-04" iyz="-2.367320e-23" izz="2.183003e-04"/>
      </inertial>

      <collision name="collision">
        <origin xyz="0 0 0" rpy="1.5707963267948966 0 0"/>
        <geometry>
          <mesh filename="package://models/thymio/meshes/thymio.dae"/>
        </geometry>
      </collision>

      <visual name="visual">
        <origin xyz="0 0 0" rpy="0 0 0"/>
        <geometry>
          <mesh filename="package://models/thymio/meshes/thymio.dae"/>
        </geometry>
      </visual>

      <collision name="raspberry_visual">
        <origin xyz="0 0 0.038" rpy="1.5707963267948966 0 0"/>
          <geometry>
            <mesh filename="package://models/thymio/meshes/raspberry_case.dae" scale="0.11 0.11 0.11"/>
          </geometry>
      </collision>

      <visual name="raspberry_visual">
        <origin xyz="0 0 0.038" rpy="0 0 0"/>
          <geometry>
            <mesh filename="package://models/thymio/meshes/raspberry_case.dae" scale="0.11 0.11 0.11"/>
          </geometry>
      </visual>
    </link>

  <link name="caster">
    <inertial>
      <inertia ixx="2.7e-6" ixy="0.0" ixz="0.0" iyy="2.7e-6" iyz="0.0" izz="2.7e-6"/>
    </inertial>
      <collision>
        <origin xyz="0.043 0 -0.021" rpy="1.5707963267948966 0 0 "/>
          <geometry>
            <cylinder length=".001" radius=".01"/>
          </geometry>
      </collision>


      <visual name="caster_visual">
         <!-- <origin xyz="0.045 0 -0.0225" rpy="0 0 0"/> -->
        <origin xyz="0.043 0 -0.021" rpy="0 0 0"/>
          <geometry>
            <sphere radius=".01"/>
          </geometry>
      </visual>
  </link>


<!-- wheels -->
  <link name="left_wheel">
    <self_collide>False</self_collide>
    <inertial>
      <inertia ixx="3.2646e-5" ixy="0.0" ixz="0.0" iyy="3.2646e-5" iyz="0.0" izz="2.7e-6"/>
    </inertial>
    <collision>
    <contact_coefficient mu="1"  resitution="0"  k_p="0"  k_d="1000" />
      <geometry>
        <cylinder length=".015" radius=".021"/>
      </geometry>
    </collision>
    <visual>
      <geometry>
        <cylinder length=".015" radius=".021"/>
      </geometry>
      <material name="ambient"/>
    </visual>
    <visual>
      <origin rpy="0 0 0" xyz="0.01 0 0.01"/>
      <geometry>
        <sphere radius=".005"/>
      </geometry>
	  <material name="green">
        <color rgba="0 1.0 0 1.0"/>
  	  </material>
    </visual>
  </link>

  <link name="right_wheel">
    <self_collide>False</self_collide>
    <inertial>
      <inertia ixx="3.2646e-5" ixy="0.0" ixz="0.0" iyy="3.2646e-5" iyz="0.0" izz="2.7e-6"/>
    </inertial>
    <collision>
    <contact_coefficient mu="1"  resitution="0"  k_p="0"  k_d="1000" />
      <geometry>
        <cylinder length=".015" radius=".021"/>
      </geometry>
    </collision>
    <visual>
      <geometry>
        <cylinder length=".015" radius=".021"/>
      </geometry>
      <material name="Front"/>
    </visual>
    <visual>
      <origin rpy="0 0 0" xyz="0.01 0 -0.01"/>
      <geometry>
        <sphere radius=".005"/>
      </geometry>
    </visual>
  </link>

<!-- revolute joints -->
  <joint name="left_wheel_hinge" type="continuous">
    <safety_controller k_position="0.0" k_velocity="40.0" soft_lower_limit="-2.8973" soft_upper_limit="2.8973"/>
    <origin rpy="0 1.5707 1.5707" xyz="-0.027 0.0475 -0.01"/>
    <child link="left_wheel"/>
    <parent link="chassis"/>
    <axis xyz="0 0 1"/>
    <dynamics damping="1.0"/>
    <limit effort="0.12" lower="-2.8973" upper="2.8973" velocity="7"/>
  </joint>
  <joint name="right_wheel_hinge" type="continuous">
    <safety_controller k_position="0.0" k_velocity="40.0" soft_lower_limit="-2.8973" soft_upper_limit="2.8973"/>
    <origin rpy="0 1.5707 1.5707" xyz="-0.027 -0.0475 -0.01"/>
    <child link="right_wheel"/>
    <parent link="chassis"/>
    <axis xyz="0 0 1"/>
    <dynamics damping="1.0"/>
    <limit effort="0.12" lower="-2.8973" upper="2.8973" velocity="7"/>
    <use_parent_model_frame>0</use_parent_model_frame>
  </joint>

    <joint name="caster_joint" type="fixed">
    <origin rpy="0 0 0" xyz="0 0 0"/>
    <child link="caster"/>
    <parent link="chassis"/>
  </joint>
</robot>
